Workbook

Sheet LerXml
A1: 11222333000181 | B1: NFE | C1: DT EMISSÃO | D1: UF | E1: Regime Tributário | F1: DESCRIÇÃO DO PRODUTO | G1: NCM | H1: CEST | I1: CFOP | J1: QTD | K1: VLR UNIT | L1: FRETE | M1: SEGURO | N1: DESCONTO | O1: OUTRAS DESPESAS | P1: VALOR TOTAL | Q1: VLR IPI | R1: ORIGEM | S1: CST | T1: ALQ ICMS NFE | U1: VLR ICMS NFE | V1: B.C ICMS ST DESTACADO | W1: ICMS ST DESTACADO | X1: MVA ICMS ST DESTACADO | Y1: Finalidade | Z1: MVA CEST | AA1: MVA NCM | AB1: MVA Escolhido | AC1: É ST? | AD1: NCM BIT? | AE1: NCM ANEXO I? | AF1: NCM ANEXO II? | AG1: Beneficio utilizado | AH1: Red B.C Antes do MVA | AI1: Total do Produto | AJ1: B.C ST Ajustado com o MVA | AK1: ICMS Interno Calculado a 17% | AL1: Crédito de ICMS Nfe | AM1: ICMS ST Calculado A Recolher | AN1: B.C Reduzida BIT (41,17%) | AO1: Déb. de ICMS Interno 17% B.C Reduzida | AP1: Credito ICMS Nfe (BIT) | AQ1: ICMS ST Calculado A Recolher BIT | AR1: MVA % Convenio 52/91 | AS1: BC OP PROP RED 73,33% OU 58,33% | AT1: BC OP PROD + MVA | AU1: CRÉDITO ICMS Se 4% = Nfe | AV1: Déb. de ICMS Interno 17% 51,77% OU 32,95% | AW1: ICMS ST Calculado A Recolher Conv 52/91 | AX1: Diferença de ICMS ST a Recolher (Cód 2817 | AY1: Aliquota Interestadual p/ calculo de DIFAL | AZ1: B.C Difal USO/CONS Imobilizado CG | BA1: Difal USO/CONS Imobilizado CG | BB1: Difal USO/CONS Imobilizado CONVENIO | BC1: B.C Difal USO/CONS Imobilizado ST | BD1: ICMS CALCULADO A 17% - ST | BE1: Difal USO/CONS Imobilizado ST | BF1: ICMS_OUTROS | BG1: CFOP Entrada
D2: =CONCATENATE(A1, " ",TEXT(MEDIAN(C3:C84750),"mm-aaaa")," - ",TEXT(E2,"dd-mm-aaaa hh-mm")) -> #VALUE! | E2: =NOW() -> 46297.35 | F2: Não mexer nessa linha - Siga as instruções | M2: BIT | N2: ANEXO I | O2: ANEXO II | P2: Pneus | Q2: - | R2: SIM | S2: NÃO | U2: CONSUMO | V2: REVENDA | Y2: REVENDA | Z2: =IF(B2="","",(IFERROR(VLOOKUP(H2,Dados!A$3:B$15000,2,0),"Não Encontrado"))) | AA2: =IF(B2="","",(IFERROR(VLOOKUP(G2,Dados!C$3:E$15000,3,0),"Não Encontrado"))) | AB2: =IFERROR(IF(Z2<>"Não Encontrado",Z2,IF(AA2<>"Não Encontrado",AA2,"")),"") | AC2: =IF(B2="","",IF(AB2="","NÃO","SIM")) | AD2: =IFERROR(VLOOKUP(G2,Dados!$P$3:$R$500,3,0),"") | AE2: =IFERROR(VLOOKUP(G2,Dados!$K$3:$L$500,2,0),"") | AF2: =IFERROR(VLOOKUP(G2,Dados!$M$3:$N$500,2,0),"") | AG2: =IF(F2="","",IF(AND(AD2="",AE2="",AF2=""),"-",IF(AND(AD2="BIT",AE2="",AF2=""),"BIT",IF(AND(AE2="ANEXO I",AD2="",AF2=""),"ANEXO I",IF(AND(AF2="ANEXO II",AD2="",AE2=""),"ANEXO II","Escolher"))))) -> - | AH2: =IF(AG2<>"Pneus","",IFERROR(VLOOKUP(R2,Dados!$X$2:$Z$5,3,0)*(AI2-Q2),VLOOKUP(D2,Dados!$X$7:$Z$33,3,0)*(AI2-Q2))) | AI2: =IF(B2="","",P2+Q2+O2+M2+L2-N2) | AJ2: =IFERROR(IF(AND(AC2="SIM",AG2="-",Y2="REVENDA"),(AB2/1+1)*AI2,IF(AND(AC2="SIM",AG2="Pneus",Y2="REVENDA"),(AB2/1+1)*(AI2-AH2),"")),"") | AK2: =IF(AJ2="","",AJ2*17%) | AL2: =IFERROR(IF(AC2="NÃO","",IF(AK2="","",IF(E2="Simples Nacional",BF2,IF(T2=0.12,U2*0.5833337002,IF(T2=0,AI2*0.07,U2))))),"") | AM2: =IFERROR(IF(AC2="NÃO","",IF(OR(AG2="-",AG2="Pneus"),AK2-AL2,"")),"") | AN2: =IF(AND(Y2="REVENDA",AC2="SIM",AG2="BIT"),((AB2/1+1)*AI2)*0.4117,"") | AO2: =IF(AN2="","",AN2*17%) | AP2: =IF(AN2="","",IF(T2=0.12,(U2*0.4117)*0.4117,IF(T2=0,(AI2*0.07)*0.4117,U2*0.4117))) | AQ2: =IF(AN2="","",AO2-AP2) | AR2: =IFERROR(IF(AND(AC2="SIM",Y2="REVENDA",LEFT(AG2,5)="ANEXO")*OR(AE2="ANEXO I",AF2="ANEXO II"),VLOOKUP(H2,Dados!G:I,2,0),""),"INSERIR MVA") | AS2: =IF(LEFT(AG2,5)="ANEXO",VLOOKUP(AG2,Dados!$X$111:$Z$112,2,0)*(AI2-Q2),"") | AT2: =IFERROR(IF(AR2="","",(AI2*AR2)+AI2),"INSERIR MVA") | AU2: =IF(AT2="","",IF(AY2=0.04,U2,AS2*AY2)) | AV2: =IFERROR(IF(AU2="","",(VLOOKUP(AG2,Dados!$X$111:$Z$112,3,0)*AT2*0.17)),"INSERIR MVA") | AW2: =IFERROR(IF(AR2="","",AV2-AU2),"") | AX2: =IFERROR(IF(AC2="NÃO","",IF(AM2<>"",AM2-W2,IF(AQ2<>"",AQ2-W2,IF(AW2<>"",AW2-W2,"")))),"") | AY2: =IFERROR(IF(ISNA(VLOOKUP(R2,Dados!$X$2:$Y$5,2,0)),VLOOKUP(D2,Dados!$X$7:$Y$33,2,0),VLOOKUP(R2,Dados!$X$2:$Y$5,2,0)),"") | AZ2: =IF(C2="","",IF(AND(Y2="CONSUMO",AC2="NÃO")*OR(AG2="-",AG2="BIT"),IF(E2<>"",(AI2-(P2+L2-N2+Q2)*AY2)/0.83),"")) | BA2: =IF(AZ2="","",AZ2*0.17-((P2+L2-N2+Q2)*AY2)) | BB2: =IF(AND(Y2="CONSUMO",AG2="ANEXO I",AY2>4%),(AI2-(P2+L2-N2+Q2)*0.0514)/0.83*(0.5177)*(0.17)-AI2*0.0514,IF(AND(Y2="CONSUMO",AG2="ANEXO II",AY2>4%),(AI2-(P2+L2-N2+Q2)*0.041)/0.83*(0.3295)*(0.17)-AI2*0.041,IF(AND(Y2="CONSUMO",AG2="ANEXO I",AY2=4%),(AI2-(P2+L2-N2+Q2)*0.04)/0.83*(0.5177)*(0.17)-AI2*0.04,IF(AND(Y2="CONSUMO",AG2="ANEXO II",AY2=4%),(AI2-(P2+L2-N2+Q2)*0.04)/0.83*(0.3295)*(0.17)-AI2*0.04,"")))) | BC2: =IF(C2="","",IF(AND(Y2="CONSUMO",AC2="SIM")*OR(AG2="-",AG2="BIT"),IF(E2<>"",(AI2-(P2+L2-N2+Q2)*AY2)/0.83),"")) | BD2: =IF(BC2="","",BC2*0.17) | BE2: =IF(I2=6908,0,IF(BC2="","",BD2-((P2+L2-N2+Q2)*AY2))) | BF2: =IF(B2="","",IF(OR(B2="",E2="Regime Normal"),0,(AI2-Q2)*VLOOKUP(R2,Dados!$X$98:$Y$108,2,0))) | BG2: =IFERROR(VLOOKUP(I2,Dados!$AC$27:$AD$43,2,0),IF(B2="","",IF(D2<>"MT",IF(AND(AC2="SIM",Y2="Revenda"),"2403",IF(AND(AC2="SIM",Y2="Consumo"),"2407",IF(AND(AC2="NÃO",Y2="Revenda"),"2102",IF(AND(AC2="NÃO",Y2="Consumo"),"2556",)))),REPLACE(I2,1,1,1))))
Z3: =IF(B3="","",(IFERROR(VLOOKUP(H3,Dados!A$3:B$15000,2,0),"Não Encontrado"))) | AA3: =IF(B3="","",(IFERROR(VLOOKUP(G3,Dados!C$3:E$15000,3,0),"Não Encontrado"))) | AB3: =IFERROR(IF(Z3<>"Não Encontrado",Z3,IF(AA3<>"Não Encontrado",AA3,"")),"") | AC3: =IF(B3="","",IF(AB3="","NÃO","SIM")) | AD3: =IFERROR(VLOOKUP(G3,Dados!$P$3:$R$500,3,0),"") | AE3: =IFERROR(VLOOKUP(G3,Dados!$K$3:$L$500,2,0),"") | AF3: =IFERROR(VLOOKUP(G3,Dados!$M$3:$N$500,2,0),"") | AG3: =IF(F3="","",IF(AND(AD3="",AE3="",AF3=""),"-",IF(AND(AD3="BIT",AE3="",AF3=""),"BIT",IF(AND(AE3="ANEXO I",AD3="",AF3=""),"ANEXO I",IF(AND(AF3="ANEXO II",AD3="",AE3=""),"ANEXO II","Escolher"))))) | AH3: =IF(AG3<>"Pneus","",IFERROR(VLOOKUP(R3,Dados!$X$2:$Z$5,3,0)*(AI3-Q3),VLOOKUP(D3,Dados!$X$7:$Z$33,3,0)*(AI3-Q3))) | AI3: =IF(B3="","",P3+Q3+O3+M3+L3-N3) | AJ3: =IFERROR(IF(AND(AC3="SIM",AG3="-",Y3="REVENDA"),(AB3/1+1)*AI3,IF(AND(AC3="SIM",AG3="Pneus",Y3="REVENDA"),(AB3/1+1)*(AI3-AH3),"")),"") | AK3: =IF(AJ3="","",AJ3*17%) | AL3: =IFERROR(IF(AC3="NÃO","",IF(AK3="","",IF(E3="Simples Nacional",BF3,IF(T3=0.12,U3*0.5833337002,IF(T3=0,AI3*0.07,U3))))),"") | AM3: =IFERROR(IF(AC3="NÃO","",IF(OR(AG3="-",AG3="Pneus"),AK3-AL3,"")),"") | AN3: =IF(AND(Y3="REVENDA",AC3="SIM",AG3="BIT"),((AB3/1+1)*AI3)*0.4117,"") | AO3: =IF(AN3="","",AN3*17%) | AP3: =IF(AN3="","",IF(T3=0.12,(U3*0.4117)*0.4117,IF(T3=0,(AI3*0.07)*0.4117,U3*0.4117))) | AQ3: =IF(AN3="","",AO3-AP3) | AR3: =IFERROR(IF(AND(AC3="SIM",Y3="REVENDA",LEFT(AG3,5)="ANEXO")*OR(AE3="ANEXO I",AF3="ANEXO II"),VLOOKUP(H3,Dados!G:I,2,0),""),"INSERIR MVA") | AS3: =IF(LEFT(AG3,5)="ANEXO",VLOOKUP(AG3,Dados!$X$111:$Z$112,2,0)*(AI3-Q3),"") | AT3: =IFERROR(IF(AR3="","",(AI3*AR3)+AI3),"INSERIR MVA") | AU3: =IF(AT3="","",IF(AY3=0.04,U3,AS3*AY3)) | AV3: =IFERROR(IF(AU3="","",(VLOOKUP(AG3,Dados!$X$111:$Z$112,3,0)*AT3*0.17)),"INSERIR MVA") | AW3: =IFERROR(IF(AR3="","",AV3-AU3),"") | AX3: =IFERROR(IF(AC3="NÃO","",IF(AM3<>"",AM3-W3,IF(AQ3<>"",AQ3-W3,IF(AW3<>"",AW3-W3,"")))),"") | AY3: =IFERROR(IF(ISNA(VLOOKUP(R3,Dados!$X$2:$Y$5,2,0)),VLOOKUP(D3,Dados!$X$7:$Y$33,2,0),VLOOKUP(R3,Dados!$X$2:$Y$5,2,0)),"") | AZ3: =IF(C3="","",IF(AND(Y3="CONSUMO",AC3="NÃO")*OR(AG3="-",AG3="BIT"),IF(E3<>"",(AI3-(P3+L3-N3+Q3)*AY3)/0.83),"")) | BA3: =IF(AZ3="","",AZ3*0.17-((P3+L3-N3+Q3)*AY3)) | BB3: =IF(AND(Y3="CONSUMO",AG3="ANEXO I",AY3>4%),(AI3-(P3+L3-N3+Q3)*0.0514)/0.83*(0.5177)*(0.17)-AI3*0.0514,IF(AND(Y3="CONSUMO",AG3="ANEXO II",AY3>4%),(AI3-(P3+L3-N3+Q3)*0.041)/0.83*(0.3295)*(0.17)-AI3*0.041,IF(AND(Y3="CONSUMO",AG3="ANEXO I",AY3=4%),(AI3-(P3+L3-N3+Q3)*0.04)/0.83*(0.5177)*(0.17)-AI3*0.04,IF(AND(Y3="CONSUMO",AG3="ANEXO II",AY3=4%),(AI3-(P3+L3-N3+Q3)*0.04)/0.83*(0.3295)*(0.17)-AI3*0.04,"")))) | BC3: =IF(C3="","",IF(AND(Y3="CONSUMO",AC3="SIM")*OR(AG3="-",AG3="BIT"),IF(E3<>"",(AI3-(P3+L3-N3+Q3)*AY3)/0.83),"")) | BD3: =IF(BC3="","",BC3*0.17) | BE3: =IF(I3=6908,0,IF(BC3="","",BD3-((P3+L3-N3+Q3)*AY3))) | BF3: =IF(B3="","",IF(OR(B3="",E3="Regime Normal"),0,(AI3-Q3)*VLOOKUP(R3,Dados!$X$98:$Y$108,2,0))) | BG3: =IFERROR(VLOOKUP(I3,Dados!$AC$27:$AD$43,2,0),IF(B3="","",IF(D3<>"MT",IF(AND(AC3="SIM",Y3="Revenda"),"2403",IF(AND(AC3="SIM",Y3="Consumo"),"2407",IF(AND(AC3="NÃO",Y3="Revenda"),"2102",IF(AND(AC3="NÃO",Y3="Consumo"),"2556",)))),REPLACE(I3,1,1,1))))
Z4: =IF(B4="","",(IFERROR(VLOOKUP(H4,Dados!A$3:B$15000,2,0),"Não Encontrado"))) | AA4: =IF(B4="","",(IFERROR(VLOOKUP(G4,Dados!C$3:E$15000,3,0),"Não Encontrado"))) | AB4: =IFERROR(IF(Z4<>"Não Encontrado",Z4,IF(AA4<>"Não Encontrado",AA4,"")),"") | AC4: =IF(B4="","",IF(AB4="","NÃO","SIM")) | AD4: =IFERROR(VLOOKUP(G4,Dados!$P$3:$R$500,3,0),"") | AE4: =IFERROR(VLOOKUP(G4,Dados!$K$3:$L$500,2,0),"") | AF4: =IFERROR(VLOOKUP(G4,Dados!$M$3:$N$500,2,0),"") | AG4: =IF(F4="","",IF(AND(AD4="",AE4="",AF4=""),"-",IF(AND(AD4="BIT",AE4="",AF4=""),"BIT",IF(AND(AE4="ANEXO I",AD4="",AF4=""),"ANEXO I",IF(AND(AF4="ANEXO II",AD4="",AE4=""),"ANEXO II","Escolher"))))) | AH4: =IF(AG4<>"Pneus","",IFERROR(VLOOKUP(R4,Dados!$X$2:$Z$5,3,0)*(AI4-Q4),VLOOKUP(D4,Dados!$X$7:$Z$33,3,0)*(AI4-Q4))) | AI4: =IF(B4="","",P4+Q4+O4+M4+L4-N4) | AJ4: =IFERROR(IF(AND(AC4="SIM",AG4="-",Y4="REVENDA"),(AB4/1+1)*AI4,IF(AND(AC4="SIM",AG4="Pneus",Y4="REVENDA"),(AB4/1+1)*(AI4-AH4),"")),"") | AK4: =IF(AJ4="","",AJ4*17%) | AL4: =IFERROR(IF(AC4="NÃO","",IF(AK4="","",IF(E4="Simples Nacional",BF4,IF(T4=0.12,U4*0.5833337002,IF(T4=0,AI4*0.07,U4))))),"") | AM4: =IFERROR(IF(AC4="NÃO","",IF(OR(AG4="-",AG4="Pneus"),AK4-AL4,"")),"") | AN4: =IF(AND(Y4="REVENDA",AC4="SIM",AG4="BIT"),((AB4/1+1)*AI4)*0.4117,"") | AO4: =IF(AN4="","",AN4*17%) | AP4: =IF(AN4="","",IF(T4=0.12,(U4*0.4117)*0.4117,IF(T4=0,(AI4*0.07)*0.4117,U4*0.4117))) | AQ4: =IF(AN4="","",AO4-AP4) | AR4: =IFERROR(IF(AND(AC4="SIM",Y4="REVENDA",LEFT(AG4,5)="ANEXO")*OR(AE4="ANEXO I",AF4="ANEXO II"),VLOOKUP(H4,Dados!G:I,2,0),""),"INSERIR MVA") | AS4: =IF(LEFT(AG4,5)="ANEXO",VLOOKUP(AG4,Dados!$X$111:$Z$112,2,0)*(AI4-Q4),"") | AT4: =IFERROR(IF(AR4="","",(AI4*AR4)+AI4),"INSERIR MVA") | AU4: =IF(AT4="","",IF(AY4=0.04,U4,AS4*AY4)) | AV4: =IFERROR(IF(AU4="","",(VLOOKUP(AG4,Dados!$X$111:$Z$112,3,0)*AT4*0.17)),"INSERIR MVA") | AW4: =IFERROR(IF(AR4="","",AV4-AU4),"") | AX4: =IFERROR(IF(AC4="NÃO","",IF(AM4<>"",AM4-W4,IF(AQ4<>"",AQ4-W4,IF(AW4<>"",AW4-W4,"")))),"") | AY4: =IFERROR(IF(ISNA(VLOOKUP(R4,Dados!$X$2:$Y$5,2,0)),VLOOKUP(D4,Dados!$X$7:$Y$33,2,0),VLOOKUP(R4,Dados!$X$2:$Y$5,2,0)),"") | AZ4: =IF(C4="","",IF(AND(Y4="CONSUMO",AC4="NÃO")*OR(AG4="-",AG4="BIT"),IF(E4<>"",(AI4-(P4+L4-N4+Q4)*AY4)/0.83),"")) | BA4: =IF(AZ4="","",AZ4*0.17-((P4+L4-N4+Q4)*AY4)) | BB4: =IF(AND(Y4="CONSUMO",AG4="ANEXO I",AY4>4%),(AI4-(P4+L4-N4+Q4)*0.0514)/0.83*(0.5177)*(0.17)-AI4*0.0514,IF(AND(Y4="CONSUMO",AG4="ANEXO II",AY4>4%),(AI4-(P4+L4-N4+Q4)*0.041)/0.83*(0.3295)*(0.17)-AI4*0.041,IF(AND(Y4="CONSUMO",AG4="ANEXO I",AY4=4%),(AI4-(P4+L4-N4+Q4)*0.04)/0.83*(0.5177)*(0.17)-AI4*0.04,IF(AND(Y4="CONSUMO",AG4="ANEXO II",AY4=4%),(AI4-(P4+L4-N4+Q4)*0.04)/0.83*(0.3295)*(0.17)-AI4*0.04,"")))) | BC4: =IF(C4="","",IF(AND(Y4="CONSUMO",AC4="SIM")*OR(AG4="-",AG4="BIT"),IF(E4<>"",(AI4-(P4+L4-N4+Q4)*AY4)/0.83),"")) | BD4: =IF(BC4="","",BC4*0.17) | BE4: =IF(I4=6908,0,IF(BC4="","",BD4-((P4+L4-N4+Q4)*AY4))) | BF4: =IF(B4="","",IF(OR(B4="",E4="Regime Normal"),0,(AI4-Q4)*VLOOKUP(R4,Dados!$X$98:$Y$108,2,0))) | BG4: =IFERROR(VLOOKUP(I4,Dados!$AC$27:$AD$43,2,0),IF(B4="","",IF(D4<>"MT",IF(AND(AC4="SIM",Y4="Revenda"),"2403",IF(AND(AC4="SIM",Y4="Consumo"),"2407",IF(AND(AC4="NÃO",Y4="Revenda"),"2102",IF(AND(AC4="NÃO",Y4="Consumo"),"2556",)))),REPLACE(I4,1,1,1))))
Z5: =IF(B5="","",(IFERROR(VLOOKUP(H5,Dados!A$3:B$15000,2,0),"Não Encontrado"))) | AA5: =IF(B5="","",(IFERROR(VLOOKUP(G5,Dados!C$3:E$15000,3,0),"Não Encontrado"))) | AB5: =IFERROR(IF(Z5<>"Não Encontrado",Z5,IF(AA5<>"Não Encontrado",AA5,"")),"") | AC5: =IF(B5="","",IF(AB5="","NÃO","SIM")) | AD5: =IFERROR(VLOOKUP(G5,Dados!$P$3:$R$500,3,0),"") | AE5: =IFERROR(VLOOKUP(G5,Dados!$K$3:$L$500,2,0),"") | AF5: =IFERROR(VLOOKUP(G5,Dados!$M$3:$N$500,2,0),"") | AG5: =IF(F5="","",IF(AND(AD5="",AE5="",AF5=""),"-",IF(AND(AD5="BIT",AE5="",AF5=""),"BIT",IF(AND(AE5="ANEXO I",AD5="",AF5=""),"ANEXO I",IF(AND(AF5="ANEXO II",AD5="",AE5=""),"ANEXO II","Escolher"))))) | AH5: =IF(AG5<>"Pneus","",IFERROR(VLOOKUP(R5,Dados!$X$2:$Z$5,3,0)*(AI5-Q5),VLOOKUP(D5,Dados!$X$7:$Z$33,3,0)*(AI5-Q5))) | AI5: =IF(B5="","",P5+Q5+O5+M5+L5-N5) | AJ5: =IFERROR(IF(AND(AC5="SIM",AG5="-",Y5="REVENDA"),(AB5/1+1)*AI5,IF(AND(AC5="SIM",AG5="Pneus",Y5="REVENDA"),(AB5/1+1)*(AI5-AH5),"")),"") | AK5: =IF(AJ5="","",AJ5*17%) | AL5: =IFERROR(IF(AC5="NÃO","",IF(AK5="","",IF(E5="Simples Nacional",BF5,IF(T5=0.12,U5*0.5833337002,IF(T5=0,AI5*0.07,U5))))),"") | AM5: =IFERROR(IF(AC5="NÃO","",IF(OR(AG5="-",AG5="Pneus"),AK5-AL5,"")),"") | AN5: =IF(AND(Y5="REVENDA",AC5="SIM",AG5="BIT"),((AB5/1+1)*AI5)*0.4117,"") | AO5: =IF(AN5="","",AN5*17%) | AP5: =IF(AN5="","",IF(T5=0.12,(U5*0.4117)*0.4117,IF(T5=0,(AI5*0.07)*0.4117,U5*0.4117))) | AQ5: =IF(AN5="","",AO5-AP5) | AR5: =IFERROR(IF(AND(AC5="SIM",Y5="REVENDA",LEFT(AG5,5)="ANEXO")*OR(AE5="ANEXO I",AF5="ANEXO II"),VLOOKUP(H5,Dados!G:I,2,0),""),"INSERIR MVA") | AS5: =IF(LEFT(AG5,5)="ANEXO",VLOOKUP(AG5,Dados!$X$111:$Z$112,2,0)*(AI5-Q5),"") | AT5: =IFERROR(IF(AR5="","",(AI5*AR5)+AI5),"INSERIR MVA") | AU5: =IF(AT5="","",IF(AY5=0.04,U5,AS5*AY5)) | AV5: =IFERROR(IF(AU5="","",(VLOOKUP(AG5,Dados!$X$111:$Z$112,3,0)*AT5*0.17)),"INSERIR MVA") | AW5: =IFERROR(IF(AR5="","",AV5-AU5),"") | AX5: =IFERROR(IF(AC5="NÃO","",IF(AM5<>"",AM5-W5,IF(AQ5<>"",AQ5-W5,IF(AW5<>"",AW5-W5,"")))),"") | AY5: =IFERROR(IF(ISNA(VLOOKUP(R5,Dados!$X$2:$Y$5,2,0)),VLOOKUP(D5,Dados!$X$7:$Y$33,2,0),VLOOKUP(R5,Dados!$X$2:$Y$5,2,0)),"") | AZ5: =IF(C5="","",IF(AND(Y5="CONSUMO",AC5="NÃO")*OR(AG5="-",AG5="BIT"),IF(E5<>"",(AI5-(P5+L5-N5+Q5)*AY5)/0.83),"")) | BA5: =IF(AZ5="","",AZ5*0.17-((P5+L5-N5+Q5)*AY5)) | BB5: =IF(AND(Y5="CONSUMO",AG5="ANEXO I",AY5>4%),(AI5-(P5+L5-N5+Q5)*0.0514)/0.83*(0.5177)*(0.17)-AI5*0.0514,IF(AND(Y5="CONSUMO",AG5="ANEXO II",AY5>4%),(AI5-(P5+L5-N5+Q5)*0.041)/0.83*(0.3295)*(0.17)-AI5*0.041,IF(AND(Y5="CONSUMO",AG5="ANEXO I",AY5=4%),(AI5-(P5+L5-N5+Q5)*0.04)/0.83*(0.5177)*(0.17)-AI5*0.04,IF(AND(Y5="CONSUMO",AG5="ANEXO II",AY5=4%),(AI5-(P5+L5-N5+Q5)*0.04)/0.83*(0.3295)*(0.17)-AI5*0.04,"")))) | BC5: =IF(C5="","",IF(AND(Y5="CONSUMO",AC5="SIM")*OR(AG5="-",AG5="BIT"),IF(E5<>"",(AI5-(P5+L5-N5+Q5)*AY5)/0.83),"")) | BD5: =IF(BC5="","",BC5*0.17) | BE5: =IF(I5=6908,0,IF(BC5="","",BD5-((P5+L5-N5+Q5)*AY5))) | BF5: =IF(B5="","",IF(OR(B5="",E5="Regime Normal"),0,(AI5-Q5)*VLOOKUP(R5,Dados!$X$98:$Y$108,2,0))) | BG5: =IFERROR(VLOOKUP(I5,Dados!$AC$27:$AD$43,2,0),IF(B5="","",IF(D5<>"MT",IF(AND(AC5="SIM",Y5="Revenda"),"2403",IF(AND(AC5="SIM",Y5="Consumo"),"2407",IF(AND(AC5="NÃO",Y5="Revenda"),"2102",IF(AND(AC5="NÃO",Y5="Consumo"),"2556",)))),REPLACE(I5,1,1,1))))
Z6: =IF(B6="","",(IFERROR(VLOOKUP(H6,Dados!A$3:B$15000,2,0),"Não Encontrado"))) | AA6: =IF(B6="","",(IFERROR(VLOOKUP(G6,Dados!C$3:E$15000,3,0),"Não Encontrado"))) | AB6: =IFERROR(IF(Z6<>"Não Encontrado",Z6,IF(AA6<>"Não Encontrado",AA6,"")),"") | AC6: =IF(B6="","",IF(AB6="","NÃO","SIM")) | AD6: =IFERROR(VLOOKUP(G6,Dados!$P$3:$R$500,3,0),"") | AE6: =IFERROR(VLOOKUP(G6,Dados!$K$3:$L$500,2,0),"") | AF6: =IFERROR(VLOOKUP(G6,Dados!$M$3:$N$500,2,0),"") | AG6: =IF(F6="","",IF(AND(AD6="",AE6="",AF6=""),"-",IF(AND(AD6="BIT",AE6="",AF6=""),"BIT",IF(AND(AE6="ANEXO I",AD6="",AF6=""),"ANEXO I",IF(AND(AF6="ANEXO II",AD6="",AE6=""),"ANEXO II","Escolher"))))) | AH6: =IF(AG6<>"Pneus","",IFERROR(VLOOKUP(R6,Dados!$X$2:$Z$5,3,0)*(AI6-Q6),VLOOKUP(D6,Dados!$X$7:$Z$33,3,0)*(AI6-Q6))) | AI6: =IF(B6="","",P6+Q6+O6+M6+L6-N6) | AJ6: =IFERROR(IF(AND(AC6="SIM",AG6="-",Y6="REVENDA"),(AB6/1+1)*AI6,IF(AND(AC6="SIM",AG6="Pneus",Y6="REVENDA"),(AB6/1+1)*(AI6-AH6),"")),"") | AK6: =IF(AJ6="","",AJ6*17%) | AL6: =IFERROR(IF(AC6="NÃO","",IF(AK6="","",IF(E6="Simples Nacional",BF6,IF(T6=0.12,U6*0.5833337002,IF(T6=0,AI6*0.07,U6))))),"") | AM6: =IFERROR(IF(AC6="NÃO","",IF(OR(AG6="-",AG6="Pneus"),AK6-AL6,"")),"") | AN6: =IF(AND(Y6="REVENDA",AC6="SIM",AG6="BIT"),((AB6/1+1)*AI6)*0.4117,"") | AO6: =IF(AN6="","",AN6*17%) | AP6: =IF(AN6="","",IF(T6=0.12,(U6*0.4117)*0.4117,IF(T6=0,(AI6*0.07)*0.4117,U6*0.4117))) | AQ6: =IF(AN6="","",AO6-AP6) | AR6: =IFERROR(IF(AND(AC6="SIM",Y6="REVENDA",LEFT(AG6,5)="ANEXO")*OR(AE6="ANEXO I",AF6="ANEXO II"),VLOOKUP(H6,Dados!G:I,2,0),""),"INSERIR MVA") | AS6: =IF(LEFT(AG6,5)="ANEXO",VLOOKUP(AG6,Dados!$X$111:$Z$112,2,0)*(AI6-Q6),"") | AT6: =IFERROR(IF(AR6="","",(AI6*AR6)+AI6),"INSERIR MVA") | AU6: =IF(AT6="","",IF(AY6=0.04,U6,AS6*AY6)) | AV6: =IFERROR(IF(AU6="","",(VLOOKUP(AG6,Dados!$X$111:$Z$112,3,0)*AT6*0.17)),"INSERIR MVA") | AW6: =IFERROR(IF(AR6="","",AV6-AU6),"") | AX6: =IFERROR(IF(AC6="NÃO","",IF(AM6<>"",AM6-W6,IF(AQ6<>"",AQ6-W6,IF(AW6<>"",AW6-W6,"")))),"") | AY6: =IFERROR(IF(ISNA(VLOOKUP(R6,Dados!$X$2:$Y$5,2,0)),VLOOKUP(D6,Dados!$X$7:$Y$33,2,0),VLOOKUP(R6,Dados!$X$2:$Y$5,2,0)),"") | AZ6: =IF(C6="","",IF(AND(Y6="CONSUMO",AC6="NÃO")*OR(AG6="-",AG6="BIT"),IF(E6<>"",(AI6-(P6+L6-N6+Q6)*AY6)/0.83),"")) | BA6: =IF(AZ6="","",AZ6*0.17-((P6+L6-N6+Q6)*AY6)) | BB6: =IF(AND(Y6="CONSUMO",AG6="ANEXO I",AY6>4%),(AI6-(P6+L6-N6+Q6)*0.0514)/0.83*(0.5177)*(0.17)-AI6*0.0514,IF(AND(Y6="CONSUMO",AG6="ANEXO II",AY6>4%),(AI6-(P6+L6-N6+Q6)*0.041)/0.83*(0.3295)*(0.17)-AI6*0.041,IF(AND(Y6="CONSUMO",AG6="ANEXO I",AY6=4%),(AI6-(P6+L6-N6+Q6)*0.04)/0.83*(0.5177)*(0.17)-AI6*0.04,IF(AND(Y6="CONSUMO",AG6="ANEXO II",AY6=4%),(AI6-(P6+L6-N6+Q6)*0.04)/0.83*(0.3295)*(0.17)-AI6*0.04,"")))) | BC6: =IF(C6="","",IF(AND(Y6="CONSUMO",AC6="SIM")*OR(AG6="-",AG6="BIT"),IF(E6<>"",(AI6-(P6+L6-N6+Q6)*AY6)/0.83),"")) | BD6: =IF(BC6="","",BC6*0.17) | BE6: =IF(I6=6908,0,IF(BC6="","",BD6-((P6+L6-N6+Q6)*AY6))) | BF6: =IF(B6="","",IF(OR(B6="",E6="Regime Normal"),0,(AI6-Q6)*VLOOKUP(R6,Dados!$X$98:$Y$108,2,0))) | BG6: =IFERROR(VLOOKUP(I6,Dados!$AC$27:$AD$43,2,0),IF(B6="","",IF(D6<>"MT",IF(AND(AC6="SIM",Y6="Revenda"),"2403",IF(AND(AC6="SIM",Y6="Consumo"),"2407",IF(AND(AC6="NÃO",Y6="Revenda"),"2102",IF(AND(AC6="NÃO",Y6="Consumo"),"2556",)))),REPLACE(I6,1,1,1))))
Z7: =IF(B7="","",(IFERROR(VLOOKUP(H7,Dados!A$3:B$15000,2,0),"Não Encontrado"))) | AA7: =IF(B7="","",(IFERROR(VLOOKUP(G7,Dados!C$3:E$15000,3,0),"Não Encontrado"))) | AB7: =IFERROR(IF(Z7<>"Não Encontrado",Z7,IF(AA7<>"Não Encontrado",AA7,"")),"") | AC7: =IF(B7="","",IF(AB7="","NÃO","SIM")) | AD7: =IFERROR(VLOOKUP(G7,Dados!$P$3:$R$500,3,0),"") | AE7: =IFERROR(VLOOKUP(G7,Dados!$K$3:$L$500,2,0),"") | AF7: =IFERROR(VLOOKUP(G7,Dados!$M$3:$N$500,2,0),"") | AG7: =IF(F7="","",IF(AND(AD7="",AE7="",AF7=""),"-",IF(AND(AD7="BIT",AE7="",AF7=""),"BIT",IF(AND(AE7="ANEXO I",AD7="",AF7=""),"ANEXO I",IF(AND(AF7="ANEXO II",AD7="",AE7=""),"ANEXO II","Escolher"))))) | AH7: =IF(AG7<>"Pneus","",IFERROR(VLOOKUP(R7,Dados!$X$2:$Z$5,3,0)*(AI7-Q7),VLOOKUP(D7,Dados!$X$7:$Z$33,3,0)*(AI7-Q7))) | AI7: =IF(B7="","",P7+Q7+O7+M7+L7-N7) | AJ7: =IFERROR(IF(AND(AC7="SIM",AG7="-",Y7="REVENDA"),(AB7/1+1)*AI7,IF(AND(AC7="SIM",AG7="Pneus",Y7="REVENDA"),(AB7/1+1)*(AI7-AH7),"")),"") | AK7: =IF(AJ7="","",AJ7*17%) | AL7: =IFERROR(IF(AC7="NÃO","",IF(AK7="","",IF(E7="Simples Nacional",BF7,IF(T7=0.12,U7*0.5833337002,IF(T7=0,AI7*0.07,U7))))),"") | AM7: =IFERROR(IF(AC7="NÃO","",IF(OR(AG7="-",AG7="Pneus"),AK7-AL7,"")),"") | AN7: =IF(AND(Y7="REVENDA",AC7="SIM",AG7="BIT"),((AB7/1+1)*AI7)*0.4117,"") | AO7: =IF(AN7="","",AN7*17%) | AP7: =IF(AN7="","",IF(T7=0.12,(U7*0.4117)*0.4117,IF(T7=0,(AI7*0.07)*0.4117,U7*0.4117))) | AQ7: =IF(AN7="","",AO7-AP7) | AR7: =IFERROR(IF(AND(AC7="SIM",Y7="REVENDA",LEFT(AG7,5)="ANEXO")*OR(AE7="ANEXO I",AF7="ANEXO II"),VLOOKUP(H7,Dados!G:I,2,0),""),"INSERIR MVA") | AS7: =IF(LEFT(AG7,5)="ANEXO",VLOOKUP(AG7,Dados!$X$111:$Z$112,2,0)*(AI7-Q7),"") | AT7: =IFERROR(IF(AR7="","",(AI7*AR7)+AI7),"INSERIR MVA") | AU7: =IF(AT7="","",IF(AY7=0.04,U7,AS7*AY7)) | AV7: =IFERROR(IF(AU7="","",(VLOOKUP(AG7,Dados!$X$111:$Z$112,3,0)*AT7*0.17)),"INSERIR MVA") | AW7: =IFERROR(IF(AR7="","",AV7-AU7),"") | AX7: =IFERROR(IF(AC7="NÃO","",IF(AM7<>"",AM7-W7,IF(AQ7<>"",AQ7-W7,IF(AW7<>"",AW7-W7,"")))),"") | AY7: =IFERROR(IF(ISNA(VLOOKUP(R7,Dados!$X$2:$Y$5,2,0)),VLOOKUP(D7,Dados!$X$7:$Y$33,2,0),VLOOKUP(R7,Dados!$X$2:$Y$5,2,0)),"") | AZ7: =IF(C7="","",IF(AND(Y7="CONSUMO",AC7="NÃO")*OR(AG7="-",AG7="BIT"),IF(E7<>"",(AI7-(P7+L7-N7+Q7)*AY7)/0.83),"")) | BA7: =IF(AZ7="","",AZ7*0.17-((P7+L7-N7+Q7)*AY7)) | BB7: =IF(AND(Y7="CONSUMO",AG7="ANEXO I",AY7>4%),(AI7-(P7+L7-N7+Q7)*0.0514)/0.83*(0.5177)*(0.17)-AI7*0.0514,IF(AND(Y7="CONSUMO",AG7="ANEXO II",AY7>4%),(AI7-(P7+L7-N7+Q7)*0.041)/0.83*(0.3295)*(0.17)-AI7*0.041,IF(AND(Y7="CONSUMO",AG7="ANEXO I",AY7=4%),(AI7-(P7+L7-N7+Q7)*0.04)/0.83*(0.5177)*(0.17)-AI7*0.04,IF(AND(Y7="CONSUMO",AG7="ANEXO II",AY7=4%),(AI7-(P7+L7-N7+Q7)*0.04)/0.83*(0.3295)*(0.17)-AI7*0.04,"")))) | BC7: =IF(C7="","",IF(AND(Y7="CONSUMO",AC7="SIM")*OR(AG7="-",AG7="BIT"),IF(E7<>"",(AI7-(P7+L7-N7+Q7)*AY7)/0.83),"")) | BD7: =IF(BC7="","",BC7*0.17) | BE7: =IF(I7=6908,0,IF(BC7="","",BD7-((P7+L7-N7+Q7)*AY7))) | BF7: =IF(B7="","",IF(OR(B7="",E7="Regime Normal"),0,(AI7-Q7)*VLOOKUP(R7,Dados!$X$98:$Y$108,2,0))) | BG7: =IFERROR(VLOOKUP(I7,Dados!$AC$27:$AD$43,2,0),IF(B7="","",IF(D7<>"MT",IF(AND(AC7="SIM",Y7="Revenda"),"2403",IF(AND(AC7="SIM",Y7="Consumo"),"2407",IF(AND(AC7="NÃO",Y7="Revenda"),"2102",IF(AND(AC7="NÃO",Y7="Consumo"),"2556",)))),REPLACE(I7,1,1,1))))
Z8: =IF(B8="","",(IFERROR(VLOOKUP(H8,Dados!A$3:B$15000,2,0),"Não Encontrado"))) | AA8: =IF(B8="","",(IFERROR(VLOOKUP(G8,Dados!C$3:E$15000,3,0),"Não Encontrado"))) | AB8: =IFERROR(IF(Z8<>"Não Encontrado",Z8,IF(AA8<>"Não Encontrado",AA8,"")),"") | AC8: =IF(B8="","",IF(AB8="","NÃO","SIM")) | AD8: =IFERROR(VLOOKUP(G8,Dados!$P$3:$R$500,3,0),"") | AE8: =IFERROR(VLOOKUP(G8,Dados!$K$3:$L$500,2,0),"") | AF8: =IFERROR(VLOOKUP(G8,Dados!$M$3:$N$500,2,0),"") | AG8: =IF(F8="","",IF(AND(AD8="",AE8="",AF8=""),"-",IF(AND(AD8="BIT",AE8="",AF8=""),"BIT",IF(AND(AE8="ANEXO I",AD8="",AF8=""),"ANEXO I",IF(AND(AF8="ANEXO II",AD8="",AE8=""),"ANEXO II","Escolher"))))) | AH8: =IF(AG8<>"Pneus","",IFERROR(VLOOKUP(R8,Dados!$X$2:$Z$5,3,0)*(AI8-Q8),VLOOKUP(D8,Dados!$X$7:$Z$33,3,0)*(AI8-Q8))) | AI8: =IF(B8="","",P8+Q8+O8+M8+L8-N8) | AJ8: =IFERROR(IF(AND(AC8="SIM",AG8="-",Y8="REVENDA"),(AB8/1+1)*AI8,IF(AND(AC8="SIM",AG8="Pneus",Y8="REVENDA"),(AB8/1+1)*(AI8-AH8),"")),"") | AK8: =IF(AJ8="","",AJ8*17%) | AL8: =IFERROR(IF(AC8="NÃO","",IF(AK8="","",IF(E8="Simples Nacional",BF8,IF(T8=0.12,U8*0.5833337002,IF(T8=0,AI8*0.07,U8))))),"") | AM8: =IFERROR(IF(AC8="NÃO","",IF(OR(AG8="-",AG8="Pneus"),AK8-AL8,"")),"") | AN8: =IF(AND(Y8="REVENDA",AC8="SIM",AG8="BIT"),((AB8/1+1)*AI8)*0.4117,"") | AO8: =IF(AN8="","",AN8*17%) | AP8: =IF(AN8="","",IF(T8=0.12,(U8*0.4117)*0.4117,IF(T8=0,(AI8*0.07)*0.4117,U8*0.4117))) | AQ8: =IF(AN8="","",AO8-AP8) | AR8: =IFERROR(IF(AND(AC8="SIM",Y8="REVENDA",LEFT(AG8,5)="ANEXO")*OR(AE8="ANEXO I",AF8="ANEXO II"),VLOOKUP(H8,Dados!G:I,2,0),""),"INSERIR MVA") | AS8: =IF(LEFT(AG8,5)="ANEXO",VLOOKUP(AG8,Dados!$X$111:$Z$112,2,0)*(AI8-Q8),"") | AT8: =IFERROR(IF(AR8="","",(AI8*AR8)+AI8),"INSERIR MVA") | AU8: =IF(AT8="","",IF(AY8=0.04,U8,AS8*AY8)) | AV8: =IFERROR(IF(AU8="","",(VLOOKUP(AG8,Dados!$X$111:$Z$112,3,0)*AT8*0.17)),"INSERIR MVA") | AW8: =IFERROR(IF(AR8="","",AV8-AU8),"") | AX8: =IFERROR(IF(AC8="NÃO","",IF(AM8<>"",AM8-W8,IF(AQ8<>"",AQ8-W8,IF(AW8<>"",AW8-W8,"")))),"") | AY8: =IFERROR(IF(ISNA(VLOOKUP(R8,Dados!$X$2:$Y$5,2,0)),VLOOKUP(D8,Dados!$X$7:$Y$33,2,0),VLOOKUP(R8,Dados!$X$2:$Y$5,2,0)),"") | AZ8: =IF(C8="","",IF(AND(Y8="CONSUMO",AC8="NÃO")*OR(AG8="-",AG8="BIT"),IF(E8<>"",(AI8-(P8+L8-N8+Q8)*AY8)/0.83),"")) | BA8: =IF(AZ8="","",AZ8*0.17-((P8+L8-N8+Q8)*AY8)) | BB8: =IF(AND(Y8="CONSUMO",AG8="ANEXO I",AY8>4%),(AI8-(P8+L8-N8+Q8)*0.0514)/0.83*(0.5177)*(0.17)-AI8*0.0514,IF(AND(Y8="CONSUMO",AG8="ANEXO II",AY8>4%),(AI8-(P8+L8-N8+Q8)*0.041)/0.83*(0.3295)*(0.17)-AI8*0.041,IF(AND(Y8="CONSUMO",AG8="ANEXO I",AY8=4%),(AI8-(P8+L8-N8+Q8)*0.04)/0.83*(0.5177)*(0.17)-AI8*0.04,IF(AND(Y8="CONSUMO",AG8="ANEXO II",AY8=4%),(AI8-(P8+L8-N8+Q8)*0.04)/0.83*(0.3295)*(0.17)-AI8*0.04,"")))) | BC8: =IF(C8="","",IF(AND(Y8="CONSUMO",AC8="SIM")*OR(AG8="-",AG8="BIT"),IF(E8<>"",(AI8-(P8+L8-N8+Q8)*AY8)/0.83),"")) | BD8: =IF(BC8="","",BC8*0.17) | BE8: =IF(I8=6908,0,IF(BC8="","",BD8-((P8+L8-N8+Q8)*AY8))) | BF8: =IF(B8="","",IF(OR(B8="",E8="Regime Normal"),0,(AI8-Q8)*VLOOKUP(R8,Dados!$X$98:$Y$108,2,0))) | BG8: =IFERROR(VLOOKUP(I8,Dados!$AC$27:$AD$43,2,0),IF(B8="","",IF(D8<>"MT",IF(AND(AC8="SIM",Y8="Revenda"),"2403",IF(AND(AC8="SIM",Y8="Consumo"),"2407",IF(AND(AC8="NÃO",Y8="Revenda"),"2102",IF(AND(AC8="NÃO",Y8="Consumo"),"2556",)))),REPLACE(I8,1,1,1))))
Z9: =IF(B9="","",(IFERROR(VLOOKUP(H9,Dados!A$3:B$15000,2,0),"Não Encontrado"))) | AA9: =IF(B9="","",(IFERROR(VLOOKUP(G9,Dados!C$3:E$15000,3,0),"Não Encontrado"))) | AB9: =IFERROR(IF(Z9<>"Não Encontrado",Z9,IF(AA9<>"Não Encontrado",AA9,"")),"") | AC9: =IF(B9="","",IF(AB9="","NÃO","SIM")) | AD9: =IFERROR(VLOOKUP(G9,Dados!$P$3:$R$500,3,0),"") | AE9: =IFERROR(VLOOKUP(G9,Dados!$K$3:$L$500,2,0),"") | AF9: =IFERROR(VLOOKUP(G9,Dados!$M$3:$N$500,2,0),"") | AG9: =IF(F9="","",IF(AND(AD9="",AE9="",AF9=""),"-",IF(AND(AD9="BIT",AE9="",AF9=""),"BIT",IF(AND(AE9="ANEXO I",AD9="",AF9=""),"ANEXO I",IF(AND(AF9="ANEXO II",AD9="",AE9=""),"ANEXO II","Escolher"))))) | AH9: =IF(AG9<>"Pneus","",IFERROR(VLOOKUP(R9,Dados!$X$2:$Z$5,3,0)*(AI9-Q9),VLOOKUP(D9,Dados!$X$7:$Z$33,3,0)*(AI9-Q9))) | AI9: =IF(B9="","",P9+Q9+O9+M9+L9-N9) | AJ9: =IFERROR(IF(AND(AC9="SIM",AG9="-",Y9="REVENDA"),(AB9/1+1)*AI9,IF(AND(AC9="SIM",AG9="Pneus",Y9="REVENDA"),(AB9/1+1)*(AI9-AH9),"")),"") | AK9: =IF(AJ9="","",AJ9*17%) | AL9: =IFERROR(IF(AC9="NÃO","",IF(AK9="","",IF(E9="Simples Nacional",BF9,IF(T9=0.12,U9*0.5833337002,IF(T9=0,AI9*0.07,U9))))),"") | AM9: =IFERROR(IF(AC9="NÃO","",IF(OR(AG9="-",AG9="Pneus"),AK9-AL9,"")),"") | AN9: =IF(AND(Y9="REVENDA",AC9="SIM",AG9="BIT"),((AB9/1+1)*AI9)*0.4117,"") | AO9: =IF(AN9="","",AN9*17%) | AP9: =IF(AN9="","",IF(T9=0.12,(U9*0.4117)*0.4117,IF(T9=0,(AI9*0.07)*0.4117,U9*0.4117))) | AQ9: =IF(AN9="","",AO9-AP9) | AR9: =IFERROR(IF(AND(AC9="SIM",Y9="REVENDA",LEFT(AG9,5)="ANEXO")*OR(AE9="ANEXO I",AF9="ANEXO II"),VLOOKUP(H9,Dados!G:I,2,0),""),"INSERIR MVA") | AS9: =IF(LEFT(AG9,5)="ANEXO",VLOOKUP(AG9,Dados!$X$111:$Z$112,2,0)*(AI9-Q9),"") | AT9: =IFERROR(IF(AR9="","",(AI9*AR9)+AI9),"INSERIR MVA") | AU9: =IF(AT9="","",IF(AY9=0.04,U9,AS9*AY9)) | AV9: =IFERROR(IF(AU9="","",(VLOOKUP(AG9,Dados!$X$111:$Z$112,3,0)*AT9*0.17)),"INSERIR MVA") | AW9: =IFERROR(IF(AR9="","",AV9-AU9),"") | AX9: =IFERROR(IF(AC9="NÃO","",IF(AM9<>"",AM9-W9,IF(AQ9<>"",AQ9-W9,IF(AW9<>"",AW9-W9,"")))),"") | AY9: =IFERROR(IF(ISNA(VLOOKUP(R9,Dados!$X$2:$Y$5,2,0)),VLOOKUP(D9,Dados!$X$7:$Y$33,2,0),VLOOKUP(R9,Dados!$X$2:$Y$5,2,0)),"") | AZ9: =IF(C9="","",IF(AND(Y9="CONSUMO",AC9="NÃO")*OR(AG9="-",AG9="BIT"),IF(E9<>"",(AI9-(P9+L9-N9+Q9)*AY9)/0.83),"")) | BA9: =IF(AZ9="","",AZ9*0.17-((P9+L9-N9+Q9)*AY9)) | BB9: =IF(AND(Y9="CONSUMO",AG9="ANEXO I",AY9>4%),(AI9-(P9+L9-N9+Q9)*0.0514)/0.83*(0.5177)*(0.17)-AI9*0.0514,IF(AND(Y9="CONSUMO",AG9="ANEXO II",AY9>4%),(AI9-(P9+L9-N9+Q9)*0.041)/0.83*(0.3295)*(0.17)-AI9*0.041,IF(AND(Y9="CONSUMO",AG9="ANEXO I",AY9=4%),(AI9-(P9+L9-N9+Q9)*0.04)/0.83*(0.5177)*(0.17)-AI9*0.04,IF(AND(Y9="CONSUMO",AG9="ANEXO II",AY9=4%),(AI9-(P9+L9-N9+Q9)*0.04)/0.83*(0.3295)*(0.17)-AI9*0.04,"")))) | BC9: =IF(C9="","",IF(AND(Y9="CONSUMO",AC9="SIM")*OR(AG9="-",AG9="BIT"),IF(E9<>"",(AI9-(P9+L9-N9+Q9)*AY9)/0.83),"")) | BD9: =IF(BC9="","",BC9*0.17) | BE9: =IF(I9=6908,0,IF(BC9="","",BD9-((P9+L9-N9+Q9)*AY9))) | BF9: =IF(B9="","",IF(OR(B9="",E9="Regime Normal"),0,(AI9-Q9)*VLOOKUP(R9,Dados!$X$98:$Y$108,2,0))) | BG9: =IFERROR(VLOOKUP(I9,Dados!$AC$27:$AD$43,2,0),IF(B9="","",IF(D9<>"MT",IF(AND(AC9="SIM",Y9="Revenda"),"2403",IF(AND(AC9="SIM",Y9="Consumo"),"2407",IF(AND(AC9="NÃO",Y9="Revenda"),"2102",IF(AND(AC9="NÃO",Y9="Consumo"),"2556",)))),REPLACE(I9,1,1,1))))
Z10: =IF(B10="","",(IFERROR(VLOOKUP(H10,Dados!A$3:B$15000,2,0),"Não Encontrado"))) | AA10: =IF(B10="","",(IFERROR(VLOOKUP(G10,Dados!C$3:E$15000,3,0),"Não Encontrado"))) | AB10: =IFERROR(IF(Z10<>"Não Encontrado",Z10,IF(AA10<>"Não Encontrado",AA10,"")),"") | AC10: =IF(B10="","",IF(AB10="","NÃO","SIM")) | AD10: =IFERROR(VLOOKUP(G10,Dados!$P$3:$R$500,3,0),"") | AE10: =IFERROR(VLOOKUP(G10,Dados!$K$3:$L$500,2,0),"") | AF10: =IFERROR(VLOOKUP(G10,Dados!$M$3:$N$500,2,0),"") | AG10: =IF(F10="","",IF(AND(AD10="",AE10="",AF10=""),"-",IF(AND(AD10="BIT",AE10="",AF10=""),"BIT",IF(AND(AE10="ANEXO I",AD10="",AF10=""),"ANEXO I",IF(AND(AF10="ANEXO II",AD10="",AE10=""),"ANEXO II","Escolher"))))) | AH10: =IF(AG10<>"Pneus","",IFERROR(VLOOKUP(R10,Dados!$X$2:$Z$5,3,0)*(AI10-Q10),VLOOKUP(D10,Dados!$X$7:$Z$33,3,0)*(AI10-Q10))) | AI10: =IF(B10="","",P10+Q10+O10+M10+L10-N10) | AJ10: =IFERROR(IF(AND(AC10="SIM",AG10="-",Y10="REVENDA"),(AB10/1+1)*AI10,IF(AND(AC10="SIM",AG10="Pneus",Y10="REVENDA"),(AB10/1+1)*(AI10-AH10),"")),"") | AK10: =IF(AJ10="","",AJ10*17%) | AL10: =IFERROR(IF(AC10="NÃO","",IF(AK10="","",IF(E10="Simples Nacional",BF10,IF(T10=0.12,U10*0.5833337002,IF(T10=0,AI10*0.07,U10))))),"") | AM10: =IFERROR(IF(AC10="NÃO","",IF(OR(AG10="-",AG10="Pneus"),AK10-AL10,"")),"") | AN10: =IF(AND(Y10="REVENDA",AC10="SIM",AG10="BIT"),((AB10/1+1)*AI10)*0.4117,"") | AO10: =IF(AN10="","",AN10*17%) | AP10: =IF(AN10="","",IF(T10=0.12,(U10*0.4117)*0.4117,IF(T10=0,(AI10*0.07)*0.4117,U10*0.4117))) | AQ10: =IF(AN10="","",AO10-AP10) | AR10: =IFERROR(IF(AND(AC10="SIM",Y10="REVENDA",LEFT(AG10,5)="ANEXO")*OR(AE10="ANEXO I",AF10="ANEXO II"),VLOOKUP(H10,Dados!G:I,2,0),""),"INSERIR MVA") | AS10: =IF(LEFT(AG10,5)="ANEXO",VLOOKUP(AG10,Dados!$X$111:$Z$112,2,0)*(AI10-Q10),"") | AT10: =IFERROR(IF(AR10="","",(AI10*AR10)+AI10),"INSERIR MVA") | AU10: =IF(AT10="","",IF(AY10=0.04,U10,AS10*AY10)) | AV10: =IFERROR(IF(AU10="","",(VLOOKUP(AG10,Dados!$X$111:$Z$112,3,0)*AT10*0.17)),"INSERIR MVA") | AW10: =IFERROR(IF(AR10="","",AV10-AU10),"") | AX10: =IFERROR(IF(AC10="NÃO","",IF(AM10<>"",AM10-W10,IF(AQ10<>"",AQ10-W10,IF(AW10<>"",AW10-W10,"")))),"") | AY10: =IFERROR(IF(ISNA(VLOOKUP(R10,Dados!$X$2:$Y$5,2,0)),VLOOKUP(D10,Dados!$X$7:$Y$33,2,0),VLOOKUP(R10,Dados!$X$2:$Y$5,2,0)),"") | AZ10: =IF(C10="","",IF(AND(Y10="CONSUMO",AC10="NÃO")*OR(AG10="-",AG10="BIT"),IF(E10<>"",(AI10-(P10+L10-N10+Q10)*AY10)/0.83),"")) | BA10: =IF(AZ10="","",AZ10*0.17-((P10+L10-N10+Q10)*AY10)) | BB10: =IF(AND(Y10="CONSUMO",AG10="ANEXO I",AY10>4%),(AI10-(P10+L10-N10+Q10)*0.0514)/0.83*(0.5177)*(0.17)-AI10*0.0514,IF(AND(Y10="CONSUMO",AG10="ANEXO II",AY10>4%),(AI10-(P10+L10-N10+Q10)*0.041)/0.83*(0.3295)*(0.17)-AI10*0.041,IF(AND(Y10="CONSUMO",AG10="ANEXO I",AY10=4%),(AI10-(P10+L10-N10+Q10)*0.04)/0.83*(0.5177)*(0.17)-AI10*0.04,IF(AND(Y10="CONSUMO",AG10="ANEXO II",AY10=4%),(AI10-(P10+L10-N10+Q10)*0.04)/0.83*(0.3295)*(0.17)-AI10*0.04,"")))) | BC10: =IF(C10="","",IF(AND(Y10="CONSUMO",AC10="SIM")*OR(AG10="-",AG10="BIT"),IF(E10<>"",(AI10-(P10+L10-N10+Q10)*AY10)/0.83),"")) | BD10: =IF(BC10="","",BC10*0.17) | BE10: =IF(I10=6908,0,IF(BC10="","",BD10-((P10+L10-N10+Q10)*AY10))) | BF10: =IF(B10="","",IF(OR(B10="",E10="Regime Normal"),0,(AI10-Q10)*VLOOKUP(R10,Dados!$X$98:$Y$108,2,0))) | BG10: =IFERROR(VLOOKUP(I10,Dados!$AC$27:$AD$43,2,0),IF(B10="","",IF(D10<>"MT",IF(AND(AC10="SIM",Y10="Revenda"),"2403",IF(AND(AC10="SIM",Y10="Consumo"),"2407",IF(AND(AC10="NÃO",Y10="Revenda"),"2102",IF(AND(AC10="NÃO",Y10="Consumo"),"2556",)))),REPLACE(I10,1,1,1))))
Z11: =IF(B11="","",(IFERROR(VLOOKUP(H11,Dados!A$3:B$15000,2,0),"Não Encontrado"))) | AA11: =IF(B11="","",(IFERROR(VLOOKUP(G11,Dados!C$3:E$15000,3,0),"Não Encontrado"))) | AB11: =IFERROR(IF(Z11<>"Não Encontrado",Z11,IF(AA11<>"Não Encontrado",AA11,"")),"") | AC11: =IF(B11="","",IF(AB11="","NÃO","SIM")) | AD11: =IFERROR(VLOOKUP(G11,Dados!$P$3:$R$500,3,0),"") | AE11: =IFERROR(VLOOKUP(G11,Dados!$K$3:$L$500,2,0),"") | AF11: =IFERROR(VLOOKUP(G11,Dados!$M$3:$N$500,2,0),"") | AG11: =IF(F11="","",IF(AND(AD11="",AE11="",AF11=""),"-",IF(AND(AD11="BIT",AE11="",AF11=""),"BIT",IF(AND(AE11="ANEXO I",AD11="",AF11=""),"ANEXO I",IF(AND(AF11="ANEXO II",AD11="",AE11=""),"ANEXO II","Escolher"))))) | AH11: =IF(AG11<>"Pneus","",IFERROR(VLOOKUP(R11,Dados!$X$2:$Z$5,3,0)*(AI11-Q11),VLOOKUP(D11,Dados!$X$7:$Z$33,3,0)*(AI11-Q11))) | AI11: =IF(B11="","",P11+Q11+O11+M11+L11-N11) | AJ11: =IFERROR(IF(AND(AC11="SIM",AG11="-",Y11="REVENDA"),(AB11/1+1)*AI11,IF(AND(AC11="SIM",AG11="Pneus",Y11="REVENDA"),(AB11/1+1)*(AI11-AH11),"")),"") | AK11: =IF(AJ11="","",AJ11*17%) | AL11: =IFERROR(IF(AC11="NÃO","",IF(AK11="","",IF(E11="Simples Nacional",BF11,IF(T11=0.12,U11*0.5833337002,IF(T11=0,AI11*0.07,U11))))),"") | AM11: =IFERROR(IF(AC11="NÃO","",IF(OR(AG11="-",AG11="Pneus"),AK11-AL11,"")),"") | AN11: =IF(AND(Y11="REVENDA",AC11="SIM",AG11="BIT"),((AB11/1+1)*AI11)*0.4117,"") | AO11: =IF(AN11="","",AN11*17%) | AP11: =IF(AN11="","",IF(T11=0.12,(U11*0.4117)*0.4117,IF(T11=0,(AI11*0.07)*0.4117,U11*0.4117))) | AQ11: =IF(AN11="","",AO11-AP11) | AR11: =IFERROR(IF(AND(AC11="SIM",Y11="REVENDA",LEFT(AG11,5)="ANEXO")*OR(AE11="ANEXO I",AF11="ANEXO II"),VLOOKUP(H11,Dados!G:I,2,0),""),"INSERIR MVA") | AS11: =IF(LEFT(AG11,5)="ANEXO",VLOOKUP(AG11,Dados!$X$111:$Z$112,2,0)*(AI11-Q11),"") | AT11: =IFERROR(IF(AR11="","",(AI11*AR11)+AI11),"INSERIR MVA") | AU11: =IF(AT11="","",IF(AY11=0.04,U11,AS11*AY11)) | AV11: =IFERROR(IF(AU11="","",(VLOOKUP(AG11,Dados!$X$111:$Z$112,3,0)*AT11*0.17)),"INSERIR MVA") | AW11: =IFERROR(IF(AR11="","",AV11-AU11),"") | AX11: =IFERROR(IF(AC11="NÃO","",IF(AM11<>"",AM11-W11,IF(AQ11<>"",AQ11-W11,IF(AW11<>"",AW11-W11,"")))),"") | AY11: =IFERROR(IF(ISNA(VLOOKUP(R11,Dados!$X$2:$Y$5,2,0)),VLOOKUP(D11,Dados!$X$7:$Y$33,2,0),VLOOKUP(R11,Dados!$X$2:$Y$5,2,0)),"") | AZ11: =IF(C11="","",IF(AND(Y11="CONSUMO",AC11="NÃO")*OR(AG11="-",AG11="BIT"),IF(E11<>"",(AI11-(P11+L11-N11+Q11)*AY11)/0.83),"")) | BA11: =IF(AZ11="","",AZ11*0.17-((P11+L11-N11+Q11)*AY11)) | BB11: =IF(AND(Y11="CONSUMO",AG11="ANEXO I",AY11>4%),(AI11-(P11+L11-N11+Q11)*0.0514)/0.83*(0.5177)*(0.17)-AI11*0.0514,IF(AND(Y11="CONSUMO",AG11="ANEXO II",AY11>4%),(AI11-(P11+L11-N11+Q11)*0.041)/0.83*(0.3295)*(0.17)-AI11*0.041,IF(AND(Y11="CONSUMO",AG11="ANEXO I",AY11=4%),(AI11-(P11+L11-N11+Q11)*0.04)/0.83*(0.5177)*(0.17)-AI11*0.04,IF(AND(Y11="CONSUMO",AG11="ANEXO II",AY11=4%),(AI11-(P11+L11-N11+Q11)*0.04)/0.83*(0.3295)*(0.17)-AI11*0.04,"")))) | BC11: =IF(C11="","",IF(AND(Y11="CONSUMO",AC11="SIM")*OR(AG11="-",AG11="BIT"),IF(E11<>"",(AI11-(P11+L11-N11+Q11)*AY11)/0.83),"")) | BD11: =IF(BC11="","",BC11*0.17) | BE11: =IF(I11=6908,0,IF(BC11="","",BD11-((P11+L11-N11+Q11)*AY11))) | BF11: =IF(B11="","",IF(OR(B11="",E11="Regime Normal"),0,(AI11-Q11)*VLOOKUP(R11,Dados!$X$98:$Y$108,2,0))) | BG11: =IFERROR(VLOOKUP(I11,Dados!$AC$27:$AD$43,2,0),IF(B11="","",IF(D11<>"MT",IF(AND(AC11="SIM",Y11="Revenda"),"2403",IF(AND(AC11="SIM",Y11="Consumo"),"2407",IF(AND(AC11="NÃO",Y11="Revenda"),"2102",IF(AND(AC11="NÃO",Y11="Consumo"),"2556",)))),REPLACE(I11,1,1,1))))
Z12: =IF(B12="","",(IFERROR(VLOOKUP(H12,Dados!A$3:B$15000,2,0),"Não Encontrado"))) | AA12: =IF(B12="","",(IFERROR(VLOOKUP(G12,Dados!C$3:E$15000,3,0),"Não Encontrado"))) | AB12: =IFERROR(IF(Z12<>"Não Encontrado",Z12,IF(AA12<>"Não Encontrado",AA12,"")),"") | AC12: =IF(B12="","",IF(AB12="","NÃO","SIM")) | AD12: =IFERROR(VLOOKUP(G12,Dados!$P$3:$R$500,3,0),"") | AE12: =IFERROR(VLOOKUP(G12,Dados!$K$3:$L$500,2,0),"") | AF12: =IFERROR(VLOOKUP(G12,Dados!$M$3:$N$500,2,0),"") | AG12: =IF(F12="","",IF(AND(AD12="",AE12="",AF12=""),"-",IF(AND(AD12="BIT",AE12="",AF12=""),"BIT",IF(AND(AE12="ANEXO I",AD12="",AF12=""),"ANEXO I",IF(AND(AF12="ANEXO II",AD12="",AE12=""),"ANEXO II","Escolher"))))) | AH12: =IF(AG12<>"Pneus","",IFERROR(VLOOKUP(R12,Dados!$X$2:$Z$5,3,0)*(AI12-Q12),VLOOKUP(D12,Dados!$X$7:$Z$33,3,0)*(AI12-Q12))) | AI12: =IF(B12="","",P12+Q12+O12+M12+L12-N12) | AJ12: =IFERROR(IF(AND(AC12="SIM",AG12="-",Y12="REVENDA"),(AB12/1+1)*AI12,IF(AND(AC12="SIM",AG12="Pneus",Y12="REVENDA"),(AB12/1+1)*(AI12-AH12),"")),"") | AK12: =IF(AJ12="","",AJ12*17%) | AL12: =IFERROR(IF(AC12="NÃO","",IF(AK12="","",IF(E12="Simples Nacional",BF12,IF(T12=0.12,U12*0.5833337002,IF(T12=0,AI12*0.07,U12))))),"") | AM12: =IFERROR(IF(AC12="NÃO","",IF(OR(AG12="-",AG12="Pneus"),AK12-AL12,"")),"") | AN12: =IF(AND(Y12="REVENDA",AC12="SIM",AG12="BIT"),((AB12/1+1)*AI12)*0.4117,"") | AO12: =IF(AN12="","",AN12*17%) | AP12: =IF(AN12="","",IF(T12=0.12,(U12*0.4117)*0.4117,IF(T12=0,(AI12*0.07)*0.4117,U12*0.4117))) | AQ12: =IF(AN12="","",AO12-AP12) | AR12: =IFERROR(IF(AND(AC12="SIM",Y12="REVENDA",LEFT(AG12,5)="ANEXO")*OR(AE12="ANEXO I",AF12="ANEXO II"),VLOOKUP(H12,Dados!G:I,2,0),""),"INSERIR MVA") | AS12: =IF(LEFT(AG12,5)="ANEXO",VLOOKUP(AG12,Dados!$X$111:$Z$112,2,0)*(AI12-Q12),"") | AT12: =IFERROR(IF(AR12="","",(AI12*AR12)+AI12),"INSERIR MVA") | AU12: =IF(AT12="","",IF(AY12=0.04,U12,AS12*AY12)) | AV12: =IFERROR(IF(AU12="","",(VLOOKUP(AG12,Dados!$X$111:$Z$112,3,0)*AT12*0.17)),"INSERIR MVA") | AW12: =IFERROR(IF(AR12="","",AV12-AU12),"") | AX12: =IFERROR(IF(AC12="NÃO","",IF(AM12<>"",AM12-W12,IF(AQ12<>"",AQ12-W12,IF(AW12<>"",AW12-W12,"")))),"") | AY12: =IFERROR(IF(ISNA(VLOOKUP(R12,Dados!$X$2:$Y$5,2,0)),VLOOKUP(D12,Dados!$X$7:$Y$33,2,0),VLOOKUP(R12,Dados!$X$2:$Y$5,2,0)),"") | AZ12: =IF(C12="","",IF(AND(Y12="CONSUMO",AC12="NÃO")*OR(AG12="-",AG12="BIT"),IF(E12<>"",(AI12-(P12+L12-N12+Q12)*AY12)/0.83),"")) | BA12: =IF(AZ12="","",AZ12*0.17-((P12+L12-N12+Q12)*AY12)) | BB12: =IF(AND(Y12="CONSUMO",AG12="ANEXO I",AY12>4%),(AI12-(P12+L12-N12+Q12)*0.0514)/0.83*(0.5177)*(0.17)-AI12*0.0514,IF(AND(Y12="CONSUMO",AG12="ANEXO II",AY12>4%),(AI12-(P12+L12-N12+Q12)*0.041)/0.83*(0.3295)*(0.17)-AI12*0.041,IF(AND(Y12="CONSUMO",AG12="ANEXO I",AY12=4%),(AI12-(P12+L12-N12+Q12)*0.04)/0.83*(0.5177)*(0.17)-AI12*0.04,IF(AND(Y12="CONSUMO",AG12="ANEXO II",AY12=4%),(AI12-(P12+L12-N12+Q12)*0.04)/0.83*(0.3295)*(0.17)-AI12*0.04,"")))) | BC12: =IF(C12="","",IF(AND(Y12="CONSUMO",AC12="SIM")*OR(AG12="-",AG12="BIT"),IF(E12<>"",(AI12-(P12+L12-N12+Q12)*AY12)/0.83),"")) | BD12: =IF(BC12="","",BC12*0.17) | BE12: =IF(I12=6908,0,IF(BC12="","",BD12-((P12+L12-N12+Q12)*AY12))) | BF12: =IF(B12="","",IF(OR(B12="",E12="Regime Normal"),0,(AI12-Q12)*VLOOKUP(R12,Dados!$X$98:$Y$108,2,0))) | BG12: =IFERROR(VLOOKUP(I12,Dados!$AC$27:$AD$43,2,0),IF(B12="","",IF(D12<>"MT",IF(AND(AC12="SIM",Y12="Revenda"),"2403",IF(AND(AC12="SIM",Y12="Consumo"),"2407",IF(AND(AC12="NÃO",Y12="Revenda"),"2102",IF(AND(AC12="NÃO",Y12="Consumo"),"2556",)))),REPLACE(I12,1,1,1))))
Z13: =IF(B13="","",(IFERROR(VLOOKUP(H13,Dados!A$3:B$15000,2,0),"Não Encontrado"))) | AA13: =IF(B13="","",(IFERROR(VLOOKUP(G13,Dados!C$3:E$15000,3,0),"Não Encontrado"))) | AB13: =IFERROR(IF(Z13<>"Não Encontrado",Z13,IF(AA13<>"Não Encontrado",AA13,"")),"") | AC13: =IF(B13="","",IF(AB13="","NÃO","SIM")) | AD13: =IFERROR(VLOOKUP(G13,Dados!$P$3:$R$500,3,0),"") | AE13: =IFERROR(VLOOKUP(G13,Dados!$K$3:$L$500,2,0),"") | AF13: =IFERROR(VLOOKUP(G13,Dados!$M$3:$N$500,2,0),"") | AG13: =IF(F13="","",IF(AND(AD13="",AE13="",AF13=""),"-",IF(AND(AD13="BIT",AE13="",AF13=""),"BIT",IF(AND(AE13="ANEXO I",AD13="",AF13=""),"ANEXO I",IF(AND(AF13="ANEXO II",AD13="",AE13=""),"ANEXO II","Escolher"))))) | AH13: =IF(AG13<>"Pneus","",IFERROR(VLOOKUP(R13,Dados!$X$2:$Z$5,3,0)*(AI13-Q13),VLOOKUP(D13,Dados!$X$7:$Z$33,3,0)*(AI13-Q13))) | AI13: =IF(B13="","",P13+Q13+O13+M13+L13-N13) | AJ13: =IFERROR(IF(AND(AC13="SIM",AG13="-",Y13="REVENDA"),(AB13/1+1)*AI13,IF(AND(AC13="SIM",AG13="Pneus",Y13="REVENDA"),(AB13/1+1)*(AI13-AH13),"")),"") | AK13: =IF(AJ13="","",AJ13*17%) | AL13: =IFERROR(IF(AC13="NÃO","",IF(AK13="","",IF(E13="Simples Nacional",BF13,IF(T13=0.12,U13*0.5833337002,IF(T13=0,AI13*0.07,U13))))),"") | AM13: =IFERROR(IF(AC13="NÃO","",IF(OR(AG13="-",AG13="Pneus"),AK13-AL13,"")),"") | AN13: =IF(AND(Y13="REVENDA",AC13="SIM",AG13="BIT"),((AB13/1+1)*AI13)*0.4117,"") | AO13: =IF(AN13="","",AN13*17%) | AP13: =IF(AN13="","",IF(T13=0.12,(U13*0.4117)*0.4117,IF(T13=0,(AI13*0.07)*0.4117,U13*0.4117))) | AQ13: =IF(AN13="","",AO13-AP13) | AR13: =IFERROR(IF(AND(AC13="SIM",Y13="REVENDA",LEFT(AG13,5)="ANEXO")*OR(AE13="ANEXO I",AF13="ANEXO II"),VLOOKUP(H13,Dados!G:I,2,0),""),"INSERIR MVA") | AS13: =IF(LEFT(AG13,5)="ANEXO",VLOOKUP(AG13,Dados!$X$111:$Z$112,2,0)*(AI13-Q13),"") | AT13: =IFERROR(IF(AR13="","",(AI13*AR13)+AI13),"INSERIR MVA") | AU13: =IF(AT13="","",IF(AY13=0.04,U13,AS13*AY13)) | AV13: =IFERROR(IF(AU13="","",(VLOOKUP(AG13,Dados!$X$111:$Z$112,3,0)*AT13*0.17)),"INSERIR MVA") | AW13: =IFERROR(IF(AR13="","",AV13-AU13),"") | AX13: =IFERROR(IF(AC13="NÃO","",IF(AM13<>"",AM13-W13,IF(AQ13<>"",AQ13-W13,IF(AW13<>"",AW13-W13,"")))),"") | AY13: =IFERROR(IF(ISNA(VLOOKUP(R13,Dados!$X$2:$Y$5,2,0)),VLOOKUP(D13,Dados!$X$7:$Y$33,2,0),VLOOKUP(R13,Dados!$X$2:$Y$5,2,0)),"") | AZ13: =IF(C13="","",IF(AND(Y13="CONSUMO",AC13="NÃO")*OR(AG13="-",AG13="BIT"),IF(E13<>"",(AI13-(P13+L13-N13+Q13)*AY13)/0.83),"")) | BA13: =IF(AZ13="","",AZ13*0.17-((P13+L13-N13+Q13)*AY13)) | BB13: =IF(AND(Y13="CONSUMO",AG13="ANEXO I",AY13>4%),(AI13-(P13+L13-N13+Q13)*0.0514)/0.83*(0.5177)*(0.17)-AI13*0.0514,IF(AND(Y13="CONSUMO",AG13="ANEXO II",AY13>4%),(AI13-(P13+L13-N13+Q13)*0.041)/0.83*(0.3295)*(0.17)-AI13*0.041,IF(AND(Y13="CONSUMO",AG13="ANEXO I",AY13=4%),(AI13-(P13+L13-N13+Q13)*0.04)/0.83*(0.5177)*(0.17)-AI13*0.04,IF(AND(Y13="CONSUMO",AG13="ANEXO II",AY13=4%),(AI13-(P13+L13-N13+Q13)*0.04)/0.83*(0.3295)*(0.17)-AI13*0.04,"")))) | BC13: =IF(C13="","",IF(AND(Y13="CONSUMO",AC13="SIM")*OR(AG13="-",AG13="BIT"),IF(E13<>"",(AI13-(P13+L13-N13+Q13)*AY13)/0.83),"")) | BD13: =IF(BC13="","",BC13*0.17) | BE13: =IF(I13=6908,0,IF(BC13="","",BD13-((P13+L13-N13+Q13)*AY13))) | BF13: =IF(B13="","",IF(OR(B13="",E13="Regime Normal"),0,(AI13-Q13)*VLOOKUP(R13,Dados!$X$98:$Y$108,2,0))) | BG13: =IFERROR(VLOOKUP(I13,Dados!$AC$27:$AD$43,2,0),IF(B13="","",IF(D13<>"MT",IF(AND(AC13="SIM",Y13="Revenda"),"2403",IF(AND(AC13="SIM",Y13="Consumo"),"2407",IF(AND(AC13="NÃO",Y13="Revenda"),"2102",IF(AND(AC13="NÃO",Y13="Consumo"),"2556",)))),REPLACE(I13,1,1,1))))
Z14: =IF(B14="","",(IFERROR(VLOOKUP(H14,Dados!A$3:B$15000,2,0),"Não Encontrado"))) | AA14: =IF(B14="","",(IFERROR(VLOOKUP(G14,Dados!C$3:E$15000,3,0),"Não Encontrado"))) | AB14: =IFERROR(IF(Z14<>"Não Encontrado",Z14,IF(AA14<>"Não Encontrado",AA14,"")),"") | AC14: =IF(B14="","",IF(AB14="","NÃO","SIM")) | AD14: =IFERROR(VLOOKUP(G14,Dados!$P$3:$R$500,3,0),"") | AE14: =IFERROR(VLOOKUP(G14,Dados!$K$3:$L$500,2,0),"") | AF14: =IFERROR(VLOOKUP(G14,Dados!$M$3:$N$500,2,0),"") | AG14: =IF(F14="","",IF(AND(AD14="",AE14="",AF14=""),"-",IF(AND(AD14="BIT",AE14="",AF14=""),"BIT",IF(AND(AE14="ANEXO I",AD14="",AF14=""),"ANEXO I",IF(AND(AF14="ANEXO II",AD14="",AE14=""),"ANEXO II","Escolher"))))) | AH14: =IF(AG14<>"Pneus","",IFERROR(VLOOKUP(R14,Dados!$X$2:$Z$5,3,0)*(AI14-Q14),VLOOKUP(D14,Dados!$X$7:$Z$33,3,0)*(AI14-Q14))) | AI14: =IF(B14="","",P14+Q14+O14+M14+L14-N14) | AJ14: =IFERROR(IF(AND(AC14="SIM",AG14="-",Y14="REVENDA"),(AB14/1+1)*AI14,IF(AND(AC14="SIM",AG14="Pneus",Y14="REVENDA"),(AB14/1+1)*(AI14-AH14),"")),"") | AK14: =IF(AJ14="","",AJ14*17%) | AL14: =IFERROR(IF(AC14="NÃO","",IF(AK14="","",IF(E14="Simples Nacional",BF14,IF(T14=0.12,U14*0.5833337002,IF(T14=0,AI14*0.07,U14))))),"") | AM14: =IFERROR(IF(AC14="NÃO","",IF(OR(AG14="-",AG14="Pneus"),AK14-AL14,"")),"") | AN14: =IF(AND(Y14="REVENDA",AC14="SIM",AG14="BIT"),((AB14/1+1)*AI14)*0.4117,"") | AO14: =IF(AN14="","",AN14*17%) | AP14: =IF(AN14="","",IF(T14=0.12,(U14*0.4117)*0.4117,IF(T14=0,(AI14*0.07)*0.4117,U14*0.4117))) | AQ14: =IF(AN14="","",AO14-AP14) | AR14: =IFERROR(IF(AND(AC14="SIM",Y14="REVENDA",LEFT(AG14,5)="ANEXO")*OR(AE14="ANEXO I",AF14="ANEXO II"),VLOOKUP(H14,Dados!G:I,2,0),""),"INSERIR MVA") | AS14: =IF(LEFT(AG14,5)="ANEXO",VLOOKUP(AG14,Dados!$X$111:$Z$112,2,0)*(AI14-Q14),"") | AT14: =IFERROR(IF(AR14="","",(AI14*AR14)+AI14),"INSERIR MVA") | AU14: =IF(AT14="","",IF(AY14=0.04,U14,AS14*AY14)) | AV14: =IFERROR(IF(AU14="","",(VLOOKUP(AG14,Dados!$X$111:$Z$112,3,0)*AT14*0.17)),"INSERIR MVA") | AW14: =IFERROR(IF(AR14="","",AV14-AU14),"") | AX14: =IFERROR(IF(AC14="NÃO","",IF(AM14<>"",AM14-W14,IF(AQ14<>"",AQ14-W14,IF(AW14<>"",AW14-W14,"")))),"") | AY14: =IFERROR(IF(ISNA(VLOOKUP(R14,Dados!$X$2:$Y$5,2,0)),VLOOKUP(D14,Dados!$X$7:$Y$33,2,0),VLOOKUP(R14,Dados!$X$2:$Y$5,2,0)),"") | AZ14: =IF(C14="","",IF(AND(Y14="CONSUMO",AC14="NÃO")*OR(AG14="-",AG14="BIT"),IF(E14<>"",(AI14-(P14+L14-N14+Q14)*AY14)/0.83),"")) | BA14: =IF(AZ14="","",AZ14*0.17-((P14+L14-N14+Q14)*AY14)) | BB14: =IF(AND(Y14="CONSUMO",AG14="ANEXO I",AY14>4%),(AI14-(P14+L14-N14+Q14)*0.0514)/0.83*(0.5177)*(0.17)-AI14*0.0514,IF(AND(Y14="CONSUMO",AG14="ANEXO II",AY14>4%),(AI14-(P14+L14-N14+Q14)*0.041)/0.83*(0.3295)*(0.17)-AI14*0.041,IF(AND(Y14="CONSUMO",AG14="ANEXO I",AY14=4%),(AI14-(P14+L14-N14+Q14)*0.04)/0.83*(0.5177)*(0.17)-AI14*0.04,IF(AND(Y14="CONSUMO",AG14="ANEXO II",AY14=4%),(AI14-(P14+L14-N14+Q14)*0.04)/0.83*(0.3295)*(0.17)-AI14*0.04,"")))) | BC14: =IF(C14="","",IF(AND(Y14="CONSUMO",AC14="SIM")*OR(AG14="-",AG14="BIT"),IF(E14<>"",(AI14-(P14+L14-N14+Q14)*AY14)/0.83),"")) | BD14: =IF(BC14="","",BC14*0.17) | BE14: =IF(I14=6908,0,IF(BC14="","",BD14-((P14+L14-N14+Q14)*AY14))) | BF14: =IF(B14="","",IF(OR(B14="",E14="Regime Normal"),0,(AI14-Q14)*VLOOKUP(R14,Dados!$X$98:$Y$108,2,0))) | BG14: =IFERROR(VLOOKUP(I14,Dados!$AC$27:$AD$43,2,0),IF(B14="","",IF(D14<>"MT",IF(AND(AC14="SIM",Y14="Revenda"),"2403",IF(AND(AC14="SIM",Y14="Consumo"),"2407",IF(AND(AC14="NÃO",Y14="Revenda"),"2102",IF(AND(AC14="NÃO",Y14="Consumo"),"2556",)))),REPLACE(I14,1,1,1))))
... Z2499: =IF(B2499="","",(IFERROR(VLOOKUP(H2499,Dados!A$3:B$15000,2,0),"Não Encontrado"))) | AA2499: =IF(B2499="","",(IFERROR(VLOOKUP(G2499,Dados!C$3:E$15000,3,0),"Não Encontrado"))) | AB2499: =IFERROR(IF(Z2499<>"Não Encontrado",Z2499,IF(AA2499<>"Não Encontrado",AA2499,"")),"") | AC2499: =IF(B2499="","",IF(AB2499="","NÃO","SIM")) | AD2499: =IFERROR(VLOOKUP(G2499,Dados!$P$3:$R$500,3,0),"") | AE2499: =IFERROR(VLOOKUP(G2499,Dados!$K$3:$L$500,2,0),"") | AF2499: =IFERROR(VLOOKUP(G2499,Dados!$M$3:$N$500,2,0),"") | AG2499: =IF(F2499="","",IF(AND(AD2499="",AE2499="",AF2499=""),"-",IF(AND(AD2499="BIT",AE2499="",AF2499=""),"BIT",IF(AND(AE2499="ANEXO I",AD2499="",AF2499=""),"ANEXO I",IF(AND(AF2499="ANEXO II",AD2499="",AE2499=""),"ANEXO II","Escolher"))))) | AH2499: =IF(AG2499<>"Pneus","",IFERROR(VLOOKUP(R2499,Dados!$X$2:$Z$5,3,0)*(AI2499-Q2499),VLOOKUP(D2499,Dados!$X$7:$Z$33,3,0)*(AI2499-Q2499))) | AI2499: =IF(B2499="","",P2499+Q2499+O2499+M2499+L2499-N2499) | AJ2499: =IFERROR(IF(AND(AC2499="SIM",AG2499="-",Y2499="REVENDA"),(AB2499/1+1)*AI2499,IF(AND(AC2499="SIM",AG2499="Pneus",Y2499="REVENDA"),(AB2499/1+1)*(AI2499-AH2499),"")),"") | AK2499: =IF(AJ2499="","",AJ2499*17%) | AL2499: =IFERROR(IF(AC2499="NÃO","",IF(AK2499="","",IF(E2499="Simples Nacional",BF2499,IF(T2499=0.12,U2499*0.5833337002,IF(T2499=0,AI2499*0.07,U2499))))),"") | AM2499: =IFERROR(IF(AC2499="NÃO","",IF(OR(AG2499="-",AG2499="Pneus"),AK2499-AL2499,"")),"") | AN2499: =IF(AND(Y2499="REVENDA",AC2499="SIM",AG2499="BIT"),((AB2499/1+1)*AI2499)*0.4117,"") | AO2499: =IF(AN2499="","",AN2499*17%) | AP2499: =IF(AN2499="","",IF(T2499=0.12,(U2499*0.4117)*0.4117,IF(T2499=0,(AI2499*0.07)*0.4117,U2499*0.4117))) | AQ2499: =IF(AN2499="","",AO2499-AP2499) | AR2499: =IFERROR(IF(AND(AC2499="SIM",Y2499="REVENDA",LEFT(AG2499,5)="ANEXO")*OR(AE2499="ANEXO I",AF2499="ANEXO II"),VLOOKUP(H2499,Dados!G:I,2,0),""),"INSERIR MVA") | AS2499: =IF(LEFT(AG2499,5)="ANEXO",VLOOKUP(AG2499,Dados!$X$111:$Z$112,2,0)*(AI2499-Q2499),"") | AT2499: =IFERROR(IF(AR2499="","",(AI2499*AR2499)+AI2499),"INSERIR MVA") | AU2499: =IF(AT2499="","",IF(AY2499=0.04,U2499,AS2499*AY2499)) | AV2499: =IFERROR(IF(AU2499="","",(VLOOKUP(AG2499,Dados!$X$111:$Z$112,3,0)*AT2499*0.17)),"INSERIR MVA") | AW2499: =IFERROR(IF(AR2499="","",AV2499-AU2499),"") | AX2499: =IFERROR(IF(AC2499="NÃO","",IF(AM2499<>"",AM2499-W2499,IF(AQ2499<>"",AQ2499-W2499,IF(AW2499<>"",AW2499-W2499,"")))),"") | AY2499: =IFERROR(IF(ISNA(VLOOKUP(R2499,Dados!$X$2:$Y$5,2,0)),VLOOKUP(D2499,Dados!$X$7:$Y$33,2,0),VLOOKUP(R2499,Dados!$X$2:$Y$5,2,0)),"") | AZ2499: =IF(C2499="","",IF(AND(Y2499="CONSUMO",AC2499="NÃO")*OR(AG2499="-",AG2499="BIT"),IF(E2499<>"",(AI2499-(P2499+L2499-N2499+Q2499)*AY2499)/0.83),"")) | BA2499: =IF(AZ2499="","",AZ2499*0.17-((P2499+L2499-N2499+Q2499)*AY2499)) | BB2499: =IF(AND(Y2499="CONSUMO",AG2499="ANEXO I",AY2499>4%),(AI2499-(P2499+L2499-N2499+Q2499)*0.0514)/0.83*(0.5177)*(0.17)-AI2499*0.0514,IF(AND(Y2499="CONSUMO",AG2499="ANEXO II",AY2499>4%),(AI2499-(P2499+L2499-N2499+Q2499)*0.041)/0.83*(0.3295)*(0.17)-AI2499*0.041,IF(AND(Y2499="CONSUMO",AG2499="ANEXO I",AY2499=4%),(AI2499-(P2499+L2499-N2499+Q2499)*0.04)/0.83*(0.5177)*(0.17)-AI2499*0.04,IF(AND(Y2499="CONSUMO",AG2499="ANEXO II",AY2499=4%),(AI2499-(P2499+L2499-N2499+Q2499)*0.04)/0.83*(0.3295)*(0.17)-AI2499*0.04,"")))) | BC2499: =IF(C2499="","",IF(AND(Y2499="CONSUMO",AC2499="SIM")*OR(AG2499="-",AG2499="BIT"),IF(E2499<>"",(AI2499-(P2499+L2499-N2499+Q2499)*AY2499)/0.83),"")) | BD2499: =IF(BC2499="","",BC2499*0.17) | BE2499: =IF(I2499=6908,0,IF(BC2499="","",BD2499-((P2499+L2499-N2499+Q2499)*AY2499))) | BF2499: =IF(B2499="","",IF(OR(B2499="",E2499="Regime Normal"),0,(AI2499-Q2499)*VLOOKUP(R2499,Dados!$X$98:$Y$108,2,0))) | BG2499: =IFERROR(VLOOKUP(I2499,Dados!$AC$27:$AD$43,2,0),IF(B2499="","",IF(D2499<>"MT",IF(AND(AC2499="SIM",Y2499="Revenda"),"2403",IF(AND(AC2499="SIM",Y2499="Consumo"),"2407",IF(AND(AC2499="NÃO",Y2499="Revenda"),"2102",IF(AND(AC2499="NÃO",Y2499="Consumo"),"2556",)))),REPLACE(I2499,1,1,1))))

Sheet Relatorio
A1: Chave de Acesso | B1: NFE | C1: DT EMISSÃO | D1: ICMS ST DESTACADO | E1: Diferença de ICMS ST a Recolher (Cód 2817) | F1: Difal USO/CONS Imobilizado CG | G1: Difal USO/CONS Imobilizado CONVENIO | H1: Difal USO/CONS Imobilizado ST | I1: Soma DIFAL (1317) | J1: Data P/ Pagamento | K1: CM | L1: Juros | M1: Dias em Atraso
D2: =IF($B2="", "",SUMIF(LerXml!B:B,Relatorio!B2,LerXml!W:W)) | E2: =IF($B2="", "",SUMIF(LerXml!B:B,Relatorio!B2,LerXml!AX:AX)) | F2: =IF($B2="", "",SUMIF(LerXml!B:B,Relatorio!B2,LerXml!BA:BA)) | G2: =IF($B2="", "",SUMIF(LerXml!B:B,Relatorio!B2,LerXml!BB:BB)) | H2: =IF($B2="", "",SUMIF(LerXml!B:B,Relatorio!B2,LerXml!BE:BE)) | I2: =IF(AND($F2="",$G2="",$H2=""), "", SUM(F2:H2))
C3: 45867 | D3: =IF($B3="", "",SUMIF(LerXml!B:B,Relatorio!B3,LerXml!W:W)) | E3: =IF($B3="", "",SUMIF(LerXml!B:B,Relatorio!B3,LerXml!AX:AX)) | F3: =IF($B3="", "",SUMIF(LerXml!B:B,Relatorio!B3,LerXml!BA:BA)) | G3: =IF($B3="", "",SUMIF(LerXml!B:B,Relatorio!B3,LerXml!BB:BB)) | H3: =IF($B3="", "",SUMIF(LerXml!B:B,Relatorio!B3,LerXml!BE:BE)) | I3: =IF(AND($F3="",$G3="",$H3=""), "", IF(SUM(F3:H3)-D3 < 0,0,SUM(F3:H3)-D3))
D4: =IF($B4="", "",SUMIF(LerXml!B:B,Relatorio!B4,LerXml!W:W)) | E4: =IF($B4="", "",SUMIF(LerXml!B:B,Relatorio!B4,LerXml!AX:AX)) | F4: =IF($B4="", "",SUMIF(LerXml!B:B,Relatorio!B4,LerXml!BA:BA)) | G4: =IF($B4="", "",SUMIF(LerXml!B:B,Relatorio!B4,LerXml!BB:BB)) | H4: =IF($B4="", "",SUMIF(LerXml!B:B,Relatorio!B4,LerXml!BE:BE)) | I4: =IF(AND($F4="",$G4="",$H4=""), "", IF(SUM(F4:H4)-D4 < 0,0,SUM(F4:H4)-D4))
D5: =IF($B5="", "",SUMIF(LerXml!B:B,Relatorio!B5,LerXml!W:W)) | E5: =IF($B5="", "",SUMIF(LerXml!B:B,Relatorio!B5,LerXml!AX:AX)) | F5: =IF($B5="", "",SUMIF(LerXml!B:B,Relatorio!B5,LerXml!BA:BA)) | G5: =IF($B5="", "",SUMIF(LerXml!B:B,Relatorio!B5,LerXml!BB:BB)) | H5: =IF($B5="", "",SUMIF(LerXml!B:B,Relatorio!B5,LerXml!BE:BE)) | I5: =IF(AND($F5="",$G5="",$H5=""), "", IF(SUM(F5:H5)-D5 < 0,0,SUM(F5:H5)-D5))
D6: =IF($B6="", "",SUMIF(LerXml!B:B,Relatorio!B6,LerXml!W:W)) | E6: =IF($B6="", "",SUMIF(LerXml!B:B,Relatorio!B6,LerXml!AX:AX)) | F6: =IF($B6="", "",SUMIF(LerXml!B:B,Relatorio!B6,LerXml!BA:BA)) | G6: =IF($B6="", "",SUMIF(LerXml!B:B,Relatorio!B6,LerXml!BB:BB)) | H6: =IF($B6="", "",SUMIF(LerXml!B:B,Relatorio!B6,LerXml!BE:BE)) | I6: =IF(AND($F6="",$G6="",$H6=""), "", IF(SUM(F6:H6)-D6 < 0,0,SUM(F6:H6)-D6))
D7: =IF($B7="", "",SUMIF(LerXml!B:B,Relatorio!B7,LerXml!W:W)) | E7: =IF($B7="", "",SUMIF(LerXml!B:B,Relatorio!B7,LerXml!AX:AX)) | F7: =IF($B7="", "",SUMIF(LerXml!B:B,Relatorio!B7,LerXml!BA:BA)) | G7: =IF($B7="", "",SUMIF(LerXml!B:B,Relatorio!B7,LerXml!BB:BB)) | H7: =IF($B7="", "",SUMIF(LerXml!B:B,Relatorio!B7,LerXml!BE:BE)) | I7: =IF(AND($F7="",$G7="",$H7=""), "", IF(SUM(F7:H7)-D7 < 0,0,SUM(F7:H7)-D7))
D8: =IF($B8="", "",SUMIF(LerXml!B:B,Relatorio!B8,LerXml!W:W)) | E8: =IF($B8="", "",SUMIF(LerXml!B:B,Relatorio!B8,LerXml!AX:AX)) | F8: =IF($B8="", "",SUMIF(LerXml!B:B,Relatorio!B8,LerXml!BA:BA)) | G8: =IF($B8="", "",SUMIF(LerXml!B:B,Relatorio!B8,LerXml!BB:BB)) | H8: =IF($B8="", "",SUMIF(LerXml!B:B,Relatorio!B8,LerXml!BE:BE)) | I8: =IF(AND($F8="",$G8="",$H8=""), "", IF(SUM(F8:H8)-D8 < 0,0,SUM(F8:H8)-D8))
D9: =IF($B9="", "",SUMIF(LerXml!B:B,Relatorio!B9,LerXml!W:W)) | E9: =IF($B9="", "",SUMIF(LerXml!B:B,Relatorio!B9,LerXml!AX:AX)) | F9: =IF($B9="", "",SUMIF(LerXml!B:B,Relatorio!B9,LerXml!BA:BA)) | G9: =IF($B9="", "",SUMIF(LerXml!B:B,Relatorio!B9,LerXml!BB:BB)) | H9: =IF($B9="", "",SUMIF(LerXml!B:B,Relatorio!B9,LerXml!BE:BE)) | I9: =IF(AND($F9="",$G9="",$H9=""), "", IF(SUM(F9:H9)-D9 < 0,0,SUM(F9:H9)-D9))
D10: =IF($B10="", "",SUMIF(LerXml!B:B,Relatorio!B10,LerXml!W:W)) | E10: =IF($B10="", "",SUMIF(LerXml!B:B,Relatorio!B10,LerXml!AX:AX)) | F10: =IF($B10="", "",SUMIF(LerXml!B:B,Relatorio!B10,LerXml!BA:BA)) | G10: =IF($B10="", "",SUMIF(LerXml!B:B,Relatorio!B10,LerXml!BB:BB)) | H10: =IF($B10="", "",SUMIF(LerXml!B:B,Relatorio!B10,LerXml!BE:BE)) | I10: =IF(AND($F10="",$G10="",$H10=""), "", IF(SUM(F10:H10)-D10 < 0,0,SUM(F10:H10)-D10))
D11: =IF($B11="", "",SUMIF(LerXml!B:B,Relatorio!B11,LerXml!W:W)) | E11: =IF($B11="", "",SUMIF(LerXml!B:B,Relatorio!B11,LerXml!AX:AX)) | F11: =IF($B11="", "",SUMIF(LerXml!B:B,Relatorio!B11,LerXml!BA:BA)) | G11: =IF($B11="", "",SUMIF(LerXml!B:B,Relatorio!B11,LerXml!BB:BB)) | H11: =IF($B11="", "",SUMIF(LerXml!B:B,Relatorio!B11,LerXml!BE:BE)) | I11: =IF(AND($F11="",$G11="",$H11=""), "", IF(SUM(F11:H11)-D11 < 0,0,SUM(F11:H11)-D11))
D12: =IF($B12="", "",SUMIF(LerXml!B:B,Relatorio!B12,LerXml!W:W)) | E12: =IF($B12="", "",SUMIF(LerXml!B:B,Relatorio!B12,LerXml!AX:AX)) | F12: =IF($B12="", "",SUMIF(LerXml!B:B,Relatorio!B12,LerXml!BA:BA)) | G12: =IF($B12="", "",SUMIF(LerXml!B:B,Relatorio!B12,LerXml!BB:BB)) | H12: =IF($B12="", "",SUMIF(LerXml!B:B,Relatorio!B12,LerXml!BE:BE)) | I12: =IF(AND($F12="",$G12="",$H12=""), "", IF(SUM(F12:H12)-D12 < 0,0,SUM(F12:H12)-D12))
D13: =IF($B13="", "",SUMIF(LerXml!B:B,Relatorio!B13,LerXml!W:W)) | E13: =IF($B13="", "",SUMIF(LerXml!B:B,Relatorio!B13,LerXml!AX:AX)) | F13: =IF($B13="", "",SUMIF(LerXml!B:B,Relatorio!B13,LerXml!BA:BA)) | G13: =IF($B13="", "",SUMIF(LerXml!B:B,Relatorio!B13,LerXml!BB:BB)) | H13: =IF($B13="", "",SUMIF(LerXml!B:B,Relatorio!B13,LerXml!BE:BE)) | I13: =IF(AND($F13="",$G13="",$H13=""), "", IF(SUM(F13:H13)-D13 < 0,0,SUM(F13:H13)-D13))
D14: =IF($B14="", "",SUMIF(LerXml!B:B,Relatorio!B14,LerXml!W:W)) | E14: =IF($B14="", "",SUMIF(LerXml!B:B,Relatorio!B14,LerXml!AX:AX)) | F14: =IF($B14="", "",SUMIF(LerXml!B:B,Relatorio!B14,LerXml!BA:BA)) | G14: =IF($B14="", "",SUMIF(LerXml!B:B,Relatorio!B14,LerXml!BB:BB)) | H14: =IF($B14="", "",SUMIF(LerXml!B:B,Relatorio!B14,LerXml!BE:BE)) | I14: =IF(AND($F14="",$G14="",$H14=""), "", IF(SUM(F14:H14)-D14 < 0,0,SUM(F14:H14)-D14))
D15: =IF($B15="", "",SUMIF(LerXml!B:B,Relatorio!B15,LerXml!W:W)) | E15: =IF($B15="", "",SUMIF(LerXml!B:B,Relatorio!B15,LerXml!AX:AX)) | F15: =IF($B15="", "",SUMIF(LerXml!B:B,Relatorio!B15,LerXml!BA:BA)) | G15: =IF($B15="", "",SUMIF(LerXml!B:B,Relatorio!B15,LerXml!BB:BB)) | H15: =IF($B15="", "",SUMIF(LerXml!B:B,Relatorio!B15,LerXml!BE:BE)) | I15: =IF(AND($F15="",$G15="",$H15=""), "", IF(SUM(F15:H15)-D15 < 0,0,SUM(F15:H15)-D15))
... D2499: =IF($B2499="", "",SUMIF(LerXml!B:B,Relatorio!B2499,LerXml!W:W)) | E2499: =IF($B2499="", "",SUMIF(LerXml!B:B,Relatorio!B2499,LerXml!AX:AX)) | F2499: =IF($B2499="", "",SUMIF(LerXml!B:B,Relatorio!B2499,LerXml!BA:BA)) | G2499: =IF($B2499="", "",SUMIF(LerXml!B:B,Relatorio!B2499,LerXml!BB:BB)) | H2499: =IF($B2499="", "",SUMIF(LerXml!B:B,Relatorio!B2499,LerXml!BE:BE)) | I2499: =IF(AND($F2499="",$G2499="",$H2499=""), "", IF(SUM(F2499:H2499)-D2499 < 0,0,SUM(F2499:H2499)-D2499))

Sheet Portaria 195
A1: NCM SEM PONTOS | B1: NCM 8 DIG | C1: NCM 7 DIG | D1: NCM 6 DIG | E1: NCM 5 DIG | F1: NCM 4 | G1: DESCRIÇÃO CONFORME PORTARIA | H1: MVA | I1: SEGUIMENTO
A2: 38151210 | B2: 3815.12.10 | G2: Catalisadores em colmeia cerâmica ou metálica para conversão catalítica de gases de escape de veículos e outros catalisadores | H2: 0.5039 | I2: I - AUTOPEÇAS
A3: 38151290 | B3: 3815.12.90 | G3: Catalisadores em colmeia cerâmica ou metálica para conversão catalítica de gases de escape de veículos e outros catalisadores | H3: 0.5039 | I3: I - AUTOPEÇAS
A4: 3917 | F4: 3917 | G4: Tubos e seus acessórios (por exemplo, juntas, cotovelos, flanges, uniões), de plásticos | H4: 0.5039 | I4: I - AUTOPEÇAS
A5: 39181000 | B5: 3918.10.00 | G5: Protetores de caçamba | H5: 0.5039 | I5: I - AUTOPEÇAS
A6: 39233000 | B6: 3923.30.00 | G6: Reservatórios de óleo | H6: 0.5039 | I6: I - AUTOPEÇAS
A7: 39263000 | B7: 3926.30.00 | G7: Frisos, decalques, molduras e acabamentos | H7: 0.5039 | I7: I - AUTOPEÇAS
A8: 40103 | E8: 4010.3 | G8: Correias de transmissão de borracha vulcanizada, de matérias têxteis, mesmo impregnadas, revestidas ou recobertas, de plástico, ou estratificadas com plástico ou reforçadas com metal ou com outras matérias | H8: 0.5039 | I8: I - AUTOPEÇAS
A9: 59100000 | B9: 5910.00.00 | G9: Correias de transmissão de borracha vulcanizada, de matérias têxteis, mesmo impregnadas, revestidas ou recobertas, de plástico, ou estratificadas com plástico ou reforçadas com metal ou com outras matérias | H9: 0.5039 | I9: I - AUTOPEÇAS
A10: 40169300 | B10: 4016.93.00 | G10: Juntas, gaxetas e outros elementos com função semelhante de vedação | H10: 0.5039 | I10: I - AUTOPEÇAS
A11: 4823909 | C11: 4823.90.9 | G11: Juntas, gaxetas e outros elementos com função semelhante de vedação | H11: 0.5039 | I11: I - AUTOPEÇAS
A12: 40161010 | B12: 4016.10.10 | G12: Partes de veículos automóveis, tratores e máquinas autopropulsadas | H12: 0.5039 | I12: I - AUTOPEÇAS
A13: 40169990 | B13: 4016.99.90 | G13: Tapetes, revestimentos, mesmo confeccionados, batentes, buchas e coxins | H13: 0.5039 | I13: I - AUTOPEÇAS
A14: 57050000 | B14: 5705.00.00 | G14: Tapetes, revestimentos, mesmo confeccionados, batentes, buchas e coxins | H14: 0.5039 | I14: I - AUTOPEÇAS
A15: 59039000 | B15: 5903.90.00 | G15: Tecidos impregnados, revestidos, recobertos ou estratificados, com plástico | H15: 0.5039 | I15: I - AUTOPEÇAS
A16: 59090000 | B16: 5909.00.00 | G16: Mangueiras e tubos semelhantes, de matérias têxteis, mesmo com reforço ou acessórios de outras matérias | H16: 0.5039 | I16: I - AUTOPEÇAS
A17: 63061 | E17: 6306.1 | G17: Encerados e toldos | H17: 0.5039 | I17: I - AUTOPEÇAS
A18: 65061000 | B18: 6506.10.00 | G18: Capacetes e artefatos de uso semelhante, de proteção, para uso em motocicletas, incluídos ciclomotores | H18: 0.5039 | I18: I - AUTOPEÇAS
A19: 6813 | F19: 6813 | G19: Guarnições de fricção (por exemplo, placas, rolos, tiras, segmentos, discos, anéis, pastilhas), não montadas, para freios, embreagens ou qualquer outro mecanismo de fricção, à base de amianto, de outras substâncias minerais ou de celulose, mesmo combinadas com têxteis ou outras matérias | H19: 0.5039 | I19: I - AUTOPEÇAS
A20: 70071100 | B20: 7007.11.00 | G20: Vidros de dimensões e formatos que permitam aplicação automotiva | H20: 0.5039 | I20: I - AUTOPEÇAS
A21: 70072100 | B21: 7007.21.00 | G21: Vidros de dimensões e formatos que permitam aplicação automotiva | H21: 0.5039 | I21: I - AUTOPEÇAS
A22: 70091000 | B22: 7009.10.00 | G22: Espelhos retrovisores | H22: 0.5039 | I22: I - AUTOPEÇAS
A23: 70140000 | B23: 7014.00.00 | G23: Lentes de faróis, lanternas e outros utensílios | H23: 0.5039 | I23: I - AUTOPEÇAS
A24: 73110000 | B24: 7311.00.00 | G24: Cilindro de aço para GNV (gás natural veicular) | H24: 0.5039 | I24: I - AUTOPEÇAS
A25: 73110000 | B25: 7311.00.00 | G25: Recipientes para gases comprimidos ou liquefeitos, de ferro fundido, ferro ou aço, exceto o descrito no item 18.0 | H25: 0.5039 | I25: I - AUTOPEÇAS
